Workbook

Sheet Drafkings Best Ball
A1: Year | B1: 2025 Player | C1: Team | D1: Player | E1: Position | F1: POS Rank | G1: ADP | H1: 1 | I1: 2 | J1: 3 | K1: 4 | L1: 5 | M1: 6 | N1: 7 | O1: 8 | P1: 9 | Q1: 10 | R1: 11 | S1: 12 | T1: 13 | U1: 14 | V1: TTL | W1: AVG | X1: Round | Y1: Position Pick | Z1: Boom 10 | AA1: Boom 15 | AB1: Boom 20 | AC1: Boom 25 | AD1: Boom 30 | AE1: Boom 10% | AF1: Boom 15% | AG1: Boom 20% | AH1: Boom 25% | AI1: Boom 30%
A2: 2025 | B2: Josh Allen | C2: BUF | D2: {=_xlfn.XLOOKUP(1,('26 WR'!A:A=E2)*('26 WR'!B:B=F2),'26 WR'!C:C)} -> Josh Allen | E2: QB | F2: 1 | G2: =VLOOKUP(B2,[2]FantasyPros_2025_Overall_ADP_Ra!$B$2:$E$416,4,FALSE) -> 24 | H2: 38.8 | I2: 11.8 | J2: 23 | K2: 25.9 | L2: 20.4 | M2: 17.4 | N2: 0 | O2: 23.2 | P2: 28.8 | Q2: 20.3 | R2: 44.7 | S2: 10.1 | T2: 17.7 | U2: 37.8 | V2: 374.6 | W2: 22 | X2: 1 | Y2: 1 | Z2: 15 | AA2: 13 | AB2: 11 | AC2: 5 | AD2: 3 | AE2: 0.88235294 | AF2: 0.76470588 | AG2: 0.64705882 | AH2: 0.29411765 | AI2: 0.17647059
A3: 2025 | B3: Lamar Jackson | C3: BAL | D3: {=_xlfn.XLOOKUP(1,('26 WR'!A:A=E3)*('26 WR'!B:B=F3),'26 WR'!C:C)} -> Lamar Jackson | E3: QB | F3: 2 | G3: =VLOOKUP(B3,[2]FantasyPros_2025_Overall_ADP_Ra!$B$2:$E$416,4,FALSE) -> 27 | H3: 29.4 | I3: 26.3 | J3: 27 | K3: 11.7 | L3: 0 | M3: 0 | N3: 0 | O3: 0 | P3: 25.6 | Q3: 16.6 | R3: 6.7 | S3: 7.2 | T3: 7.5 | U3: 22.1 | V3: 221.9 | W3: 17.1 | X3: 20 | Y3: 1 | Z3: 9 | AA3: 8 | AB3: 6 | AC3: 4 | AD3: 0 | AE3: 0.52941176 | AF3: 0.61538462 | AG3: 0.46153846 | AH3: 0.30769231 | AI3: 0
A4: 2025 | B4: Jayden Daniels | C4: WAS | D4: {=_xlfn.XLOOKUP(1,('26 WR'!A:A=E4)*('26 WR'!B:B=F4),'26 WR'!C:C)} -> Drake Maye | E4: QB | F4: 3 | G4: =VLOOKUP(B4,[2]FantasyPros_2025_Overall_ADP_Ra!$B$2:$E$416,4,FALSE) -> 34 | H4: 20.1 | I4: 19.7 | J4: 0 | K4: 0 | L4: 17.1 | M4: 22.6 | N4: 17.7 | O4: 0 | P4: 16.2 | Q4: 0 | R4: 0 | S4: 0 | T4: 0 | U4: 3.7 | V4: 117.3 | W4: 16.8 | X4: 34 | Y4: 1 | Z4: 6 | AA4: 6 | AB4: 2 | AC4: 0 | AD4: 0 | AE4: 0.35294118 | AF4: 0.85714286 | AG4: 0.28571429 | AH4: 0 | AI4: 0
A5: 2025 | B5: Jalen Hurts | C5: PHI | D5: {=_xlfn.XLOOKUP(1,('26 WR'!A:A=E5)*('26 WR'!B:B=F5),'26 WR'!C:C)} -> Joe Burrow | E5: QB | F5: 4 | G5: =VLOOKUP(B5,[2]FantasyPros_2025_Overall_ADP_Ra!$B$2:$E$416,4,FALSE) -> 42 | H5: 24.3 | I5: 11.5 | J5: 29 | K5: 19.4 | L5: 19.5 | M5: 21.6 | N5: 24 | O5: 25.4 | P5: 0 | Q5: 12 | R5: 14.5 | S5: 30.9 | T5: 17.3 | U5: 4.4 | V5: 305.1 | W5: 19.1 | X5: 9 | Y5: 1 | Z5: 14 | AA5: 11 | AB5: 7 | AC5: 3 | AD5: 1 | AE5: 0.82352941 | AF5: 0.6875 | AG5: 0.4375 | AH5: 0.1875 | AI5: 0.0625
A6: 2025 | B6: Joe Burrow | C6: CIN | D6: {=_xlfn.XLOOKUP(1,('26 WR'!A:A=E6)*('26 WR'!B:B=F6),'26 WR'!C:C)} -> Jayden Daniels | E6: QB | F6: 5 | G6: =VLOOKUP(B6,[2]FantasyPros_2025_Overall_ADP_Ra!$B$2:$E$416,4,FALSE) -> 45 | H6: 8.8 | I6: 7 | J6: 0 | K6: 0 | L6: 0 | M6: 0 | N6: 0 | O6: 0 | P6: 0 | Q6: 0 | R6: 0 | S6: 0 | T6: 19.2 | U6: 25.4 | V6: 139.5 | W6: 17.4 | X6: 7 | Y6: 1 | Z6: 5 | AA6: 5 | AB6: 4 | AC6: 2 | AD6: 0 | AE6: 0.29411765 | AF6: 0.625 | AG6: 0.5 | AH6: 0.25 | AI6: 0
A7: 2025 | B7: Patrick Mahomes II | C7: KC | D7: {=_xlfn.XLOOKUP(1,('26 WR'!A:A=E7)*('26 WR'!B:B=F7),'26 WR'!C:C)} -> Jalen Hurts | E7: QB | F7: 6 | G7: =VLOOKUP(B7,[2]FantasyPros_2025_Overall_ADP_Ra!$B$2:$E$416,4,FALSE) -> 72 | H7: 26 | I7: 23.1 | J7: 13.2 | K7: 27.3 | L7: 27.7 | M7: 31.5 | N7: 26.2 | O7: 25 | P7: 11.5 | Q7: 0 | R7: 14.3 | S7: 18.1 | T7: 29.4 | U7: 8.3 | V7: 295.7 | W7: 21.1 | X7: 11 | Y7: 1 | Z7: 13 | AA7: 9 | AB7: 8 | AC7: 6 | AD7: 1 | AE7: 0.76470588 | AF7: 0.64285714 | AG7: 0.57142857 | AH7: 0.42857143 | AI7: 0.071428571
A8: 2025 | B8: Baker Mayfield | C8: TB | D8: {=_xlfn.XLOOKUP(1,('26 WR'!A:A=E8)*('26 WR'!B:B=F8),'26 WR'!C:C)} -> Caleb Williams | E8: QB | F8: 7 | G8: =VLOOKUP(B8,[2]FantasyPros_2025_Overall_ADP_Ra!$B$2:$E$416,4,FALSE) -> 79 | H8: 22.6 | I8: 19.9 | J8: 17.7 | K8: 19.9 | L8: 26.7 | M8: 19.6 | N8: 12.1 | O8: 4.1 | P8: 0 | Q8: 22.9 | R8: 17.8 | S8: 5.5 | T8: 14.5 | U8: 12.1 | V8: 282.9 | W8: 16.6 | X8: 12 | Y8: 1 | Z8: 15 | AA8: 10 | AB8: 4 | AC8: 1 | AD8: 0 | AE8: 0.88235294 | AF8: 0.58823529 | AG8: 0.23529412 | AH8: 0.058823529 | AI8: 0
A9: 2025 | B9: Bo Nix | C9: DEN | D9: {=_xlfn.XLOOKUP(1,('26 WR'!A:A=E9)*('26 WR'!B:B=F9),'26 WR'!C:C)} -> Justin Herbert | E9: QB | F9: 8 | G9: =VLOOKUP(B9,[2]FantasyPros_2025_Overall_ADP_Ra!$B$2:$E$416,4,FALSE) -> 83 | H9: 8.8 | I9: 21.2 | J9: 13.4 | K9: 26.7 | L9: 17.9 | M9: 13.4 | N9: 40 | O9: 24.8 | P9: 19.5 | Q9: 7.8 | R9: 12.6 | S9: 0 | T9: 17.4 | U9: 16 | V9: 315.8 | W9: 18.6 | X9: 7 | Y9: 1 | Z9: 15 | AA9: 11 | AB9: 6 | AC9: 3 | AD9: 1 | AE9: 0.88235294 | AF9: 0.64705882 | AG9: 0.35294118 | AH9: 0.17647059 | AI9: 0.058823529
A10: 2025 | B10: Dak Prescott | C10: DAL | D10: {=_xlfn.XLOOKUP(1,('26 WR'!A:A=E10)*('26 WR'!B:B=F10),'26 WR'!C:C)} -> Trevor Lawrence | E10: QB | F10: 9 | G10: =VLOOKUP(B10,[2]FantasyPros_2025_Overall_ADP_Ra!$B$2:$E$416,4,FALSE) -> 87 | H10: 7.8 | I10: 23.1 | J10: 14 | K10: 31 | L10: 28.3 | M10: 22.3 | N10: 23.3 | O10: 8.6 | P10: 16.4 | Q10: 0 | R10: 24.3 | S10: 28.1 | T10: 21.6 | U10: 20.4 | V10: 323.8 | W10: 19 | X10: 5 | Y10: 1 | Z10: 14 | AA10: 12 | AB10: 10 | AC10: 3 | AD10: 1 | AE10: 0.82352941 | AF10: 0.70588235 | AG10: 0.58823529 | AH10: 0.17647059 | AI10: 0.058823529
A11: 2025 | B11: Kyler Murray | C11: ARI | D11: {=_xlfn.XLOOKUP(1,('26 WR'!A:A=E11)*('26 WR'!B:B=F11),'26 WR'!C:C)} -> Dak Prescott | E11: QB | F11: 10 | G11: =VLOOKUP(B11,[2]FantasyPros_2025_Overall_ADP_Ra!$B$2:$E$416,4,FALSE) -> 98 | H11: 18.3 | I11: 15 | J11: 14.1 | K11: 18.1 | L11: 15.3 | M11: 0 | N11: 0 | O11: 0 | P11: 0 | Q11: 0 | R11: 0 | S11: 0 | T11: 0 | U11: 0 | V11: 80.8 | W11: 16.2 | X11: 38 | Y11: 1 | Z11: 5 | AA11: 3 | AB11: 0 | AC11: 0 | AD11: 0 | AE11: 0.29411765 | AF11: 0.6 | AG11: 0 | AH11: 0 | AI11: 0
A12: 2025 | B12: Brock Purdy | C12: SF | D12: {=_xlfn.XLOOKUP(1,('26 WR'!A:A=E12)*('26 WR'!B:B=F12),'26 WR'!C:C)} -> Jaxson Dart | E12: QB | F12: 11 | G12: =VLOOKUP(B12,[2]FantasyPros_2025_Overall_ADP_Ra!$B$2:$E$416,4,FALSE) -> 101 | H12: 18.8 | I12: 0 | J12: 0 | K12: 19.7 | L12: 0 | M12: 0 | N12: 0 | O12: 0 | P12: 0 | Q12: 0 | R12: 19.3 | S12: 10.3 | T12: 17.1 | U12: 0 | V12: 187.4 | W12: 20.8 | X12: 15 | Y12: 1 | Z12: 8 | AA12: 7 | AB12: 3 | AC12: 3 | AD12: 2 | AE12: 0.47058824 | AF12: 0.77777778 | AG12: 0.33333333 | AH12: 0.33333333 | AI12: 0.22222222
A13: 2025 | B13: Jared Goff | C13: DET | D13: {=_xlfn.XLOOKUP(1,('26 WR'!A:A=E13)*('26 WR'!B:B=F13),'26 WR'!C:C)} -> Brock Purdy | E13: QB | F13: 12 | G13: =VLOOKUP(B13,[2]FantasyPros_2025_Overall_ADP_Ra!$B$2:$E$416,4,FALSE) -> 104 | H13: 11.9 | I13: 34 | J13: 12.7 | K13: 13.7 | L13: 20.1 | M13: 16.8 | N13: 11.3 | O13: 0 | P13: 19.4 | Q13: 24.8 | R13: 13.1 | S13: 18.2 | T13: 20.6 | U13: 16.2 | V13: 305.1 | W13: 17.9 | X13: 8 | Y13: 1 | Z13: 16 | AA13: 11 | AB13: 6 | AC13: 3 | AD13: 1 | AE13: 0.94117647 | AF13: 0.64705882 | AG13: 0.35294118 | AH13: 0.17647059 | AI13: 0.058823529
... A68: 2025 | B68: Tyrone Tracy Jr. | C68: NYG | D68: {=_xlfn.XLOOKUP(1,('26 WR'!A:A=E68)*('26 WR'!B:B=F68),'26 WR'!C:C)} -> Jadarian Price | E68: RB | F68: 27 | G68: =VLOOKUP(B68,[2]FantasyPros_2025_Overall_ADP_Ra!$B$2:$E$416,4,FALSE) -> 81 | H68: 5.5 | I68: 9.1 | J68: 5.6 | K68: 0 | L68: 0 | M68: 0.6 | N68: 10.6 | O68: 7.3 | P68: 6.7 | Q68: 8.1 | R68: 17.9 | S68: 16 | T68: 4.3 | U68: 0 | V68: 160.8 | W68: 10.7 | X68: 7 | Y68: 1 | Z68: 5 | AA68: 4 | AB68: 2 | AC68: 1 | AD68: 0 | AE68: 0.29411765 | AF68: 0.26666667 | AG68: 0.13333333 | AH68: 0.066666667 | AI68: 0
A69: 2025 | B69: Jacory Croskey Merritt | C69: WAS | D69: {=_xlfn.XLOOKUP(1,('26 WR'!A:A=E69)*('26 WR'!B:B=F69),'26 WR'!C:C)} -> Chuba Hubbard | E69: RB | F69: 28 | G69: 82 | H69: 14.2 | I69: 1.7 | J69: 10.1 | K69: 7.7 | L69: 27 | M69: 5.8 | N69: 4.2 | O69: 2.5 | P69: 5.1 | Q69: 3 | R69: 4.3 | S69: 0 | T69: 2 | U69: 3.2 | V69: 140.3 | W69: 8.3 | X69: 7 | Y69: 1 | Z69: 5 | AA69: 3 | AB69: 2 | AC69: 1 | AD69: 0 | AE69: 0.29411765 | AF69: 0.17647059 | AG69: 0.11764706 | AH69: 0.058823529 | AI69: 0
A70: 2025 | B70: Jordan Mason | C70: MIN | D70: {=_xlfn.XLOOKUP(1,('26 WR'!A:A=E70)*('26 WR'!B:B=F70),'26 WR'!C:C)} -> Rhamondre Stevenson | E70: RB | F70: 29 | G70: =VLOOKUP(B70,[2]FantasyPros_2025_Overall_ADP_Ra!$B$2:$E$416,4,FALSE) -> 86 | H70: 8.5 | I70: 5.8 | J70: 23.6 | K70: 10.2 | L70: 12.6 | M70: 0 | N70: 11.7 | O70: 1.6 | P70: 4.7 | Q70: 4.1 | R70: 10.5 | S70: 4.2 | T70: 5.8 | U70: 11.2 | V70: 128.9 | W70: 8.1 | X70: 8 | Y70: 1 | Z70: 6 | AA70: 1 | AB70: 1 | AC70: 0 | AD70: 0 | AE70: 0.35294118 | AF70: 0.0625 | AG70: 0.0625 | AH70: 0 | AI70: 0
A71: 2025 | B71: Jaylen Warren | C71: PIT | D71: {=_xlfn.XLOOKUP(1,('26 WR'!A:A=E71)*('26 WR'!B:B=F71),'26 WR'!C:C)} -> Tony Pollard | E71: RB | F71: 30 | G71: =VLOOKUP(B71,[2]FantasyPros_2025_Overall_ADP_Ra!$B$2:$E$416,4,FALSE) -> 91 | H71: 13.9 | I71: 17.4 | J71: 13.1 | K71: 0 | L71: 0 | M71: 8.3 | N71: 19.8 | O71: 9.3 | P71: 16.9 | Q71: 11.1 | R71: 8.7 | S71: 12.8 | T71: 12.4 | U71: 15.2 | V71: 217.1 | W71: 13.6 | X71: 8 | Y71: 1 | Z71: 11 | AA71: 5 | AB71: 1 | AC71: 1 | AD71: 0 | AE71: 0.64705882 | AF71: 0.3125 | AG71: 0.0625 | AH71: 0.0625 | AI71: 0
A72: 2025 | B72: Zach Charbonnet | C72: SEA | D72: {=_xlfn.XLOOKUP(1,('26 WR'!A:A=E72)*('26 WR'!B:B=F72),'26 WR'!C:C)} -> RJ Harvey | E72: RB | F72: 31 | G72: =VLOOKUP(B72,[2]FantasyPros_2025_Overall_ADP_Ra!$B$2:$E$416,4,FALSE) -> 93 | H72: 10.7 | I72: 1 | J72: 0 | K72: 12.4 | L72: 11.8 | M72: 4.7 | N72: 19.5 | O72: 0 | P72: 5.6 | Q72: 14.3 | R72: 6.7 | S72: 9.5 | T72: 11.2 | U72: 8.6 | V72: 181.4 | W72: 11.3 | X72: 8 | Y72: 1 | Z72: 9 | AA72: 4 | AB72: 1 | AC72: 1 | AD72: 0 | AE72: 0.52941176 | AF72: 0.25 | AG72: 0.0625 | AH72: 0.0625 | AI72: 0
A73: 2025 | B73: Travis Etienne Jr. | C73: JAC | D73: {=_xlfn.XLOOKUP(1,('26 WR'!A:A=E73)*('26 WR'!B:B=F73),'26 WR'!C:C)} -> Rico Dowdle | E73: RB | F73: 32 | G73: =VLOOKUP(B73,[2]FantasyPros_2025_Overall_ADP_Ra!$B$2:$E$416,4,FALSE) -> 99 | H73: 18.6 | I73: 16.9 | J73: 11.6 | K73: 19.5 | L73: 8.8 | M73: 9.5 | N73: 6.5 | O73: 0 | P73: 16.5 | Q73: 15.7 | R73: 19.3 | S73: 20.6 | T73: 5.1 | U73: 21.2 | V73: 253.9 | W73: 14.9 | X73: 9 | Y73: 1 | Z73: 12 | AA73: 10 | AB73: 3 | AC73: 1 | AD73: 1 | AE73: 0.70588235 | AF73: 0.58823529 | AG73: 0.17647059 | AH73: 0.058823529 | AI73: 0.058823529
A74: 2025 | B74: J.K. Dobbins | C74: DEN | D74: {=_xlfn.XLOOKUP(1,('26 WR'!A:A=E74)*('26 WR'!B:B=F74),'26 WR'!C:C)} -> Kenny Gainwell | E74: RB | F74: 33 | G74: =VLOOKUP(B74,[2]FantasyPros_2025_Overall_ADP_Ra!$B$2:$E$416,4,FALSE) -> 100 | H74: 14.8 | I74: 15.5 | J74: 15.3 | K74: 11.5 | L74: 15.4 | M74: 4 | N74: 9 | O74: 14.1 | P74: 6.9 | Q74: 9.4 | R74: 0 | S74: 0 | T74: 0 | U74: 0 | V74: 115.9 | W74: 11.6 | X74: 9 | Y74: 1 | Z74: 6 | AA74: 3 | AB74: 0 | AC74: 0 | AD74: 0 | AE74: 0.35294118 | AF74: 0.3 | AG74: 0 | AH74: 0 | AI74: 0
A75: 2025 | B75: Javonte Williams | C75: DAL | D75: {=_xlfn.XLOOKUP(1,('26 WR'!A:A=E75)*('26 WR'!B:B=F75),'26 WR'!C:C)} -> Kyle Monangai | E75: RB | F75: 34 | G75: =VLOOKUP(B75,[2]FantasyPros_2025_Overall_ADP_Ra!$B$2:$E$416,4,FALSE) -> 106 | H75: 20.4 | I75: 25 | J75: 12.2 | K75: 19 | L75: 26.9 | M75: 8.4 | N75: 18.8 | O75: 17.9 | P75: 7.3 | Q75: 0 | R75: 10.3 | S75: 12.1 | T75: 17 | U75: 14.7 | V75: 242.8 | W75: 15.2 | X75: 9 | Y75: 1 | Z75: 13 | AA75: 8 | AB75: 3 | AC75: 1 | AD75: 0 | AE75: 0.76470588 | AF75: 0.5 | AG75: 0.1875 | AH75: 0.0625 | AI75: 0
A76: 2025 | B76: Nick Chubb | C76: HOU | D76: {=_xlfn.XLOOKUP(1,('26 WR'!A:A=E76)*('26 WR'!B:B=F76),'26 WR'!C:C)} -> J.K. Dobbins | E76: RB | F76: 35 | G76: =VLOOKUP(B76,[2]FantasyPros_2025_Overall_ADP_Ra!$B$2:$E$416,4,FALSE) -> 112 | H76: 6 | I76: 15.2 | J76: 7 | K76: 8.2 | L76: 12.1 | M76: 0 | N76: 2.1 | O76: 8.9 | P76: 3.4 | Q76: 6.2 | R76: 1.7 | S76: 2.5 | T76: 9.4 | U76: 0.3 | V76: 88.3 | W76: 5.9 | X76: 10 | Y76: 1 | Z76: 2 | AA76: 1 | AB76: 0 | AC76: 0 | AD76: 0 | AE76: 0.11764706 | AF76: 0.066666667 | AG76: 0 | AH76: 0 | AI76: 0
A77: 2025 | B77: Cam Skattebo | C77: NYG | D77: {=_xlfn.XLOOKUP(1,('26 WR'!A:A=E77)*('26 WR'!B:B=F77),'26 WR'!C:C)} -> Aaron Jones Sr. | E77: RB | F77: 36 | G77: =VLOOKUP(B77,[2]FantasyPros_2025_Overall_ADP_Ra!$B$2:$E$416,4,FALSE) -> 119 | H77: 2.9 | I77: 13.9 | J77: 24.1 | K77: 13 | L77: 14.4 | M77: 31 | N77: 18.4 | O77: 10 | P77: 0 | Q77: 0 | R77: 0 | S77: 0 | T77: 0 | U77: 0 | V77: 127.7 | W77: 16 | X77: 10 | Y77: 1 | Z77: 6 | AA77: 3 | AB77: 2 | AC77: 1 | AD77: 1 | AE77: 0.35294118 | AF77: 0.375 | AG77: 0.25 | AH77: 0.125 | AI77: 0.125
A78: 2025 | B78: Braelon Allen | C78: NYJ | D78: {=_xlfn.XLOOKUP(1,('26 WR'!A:A=E78)*('26 WR'!B:B=F78),'26 WR'!C:C)} -> Blake Corum | E78: RB | F78: 37 | G78: =VLOOKUP(B78,[2]FantasyPros_2025_Overall_ADP_Ra!$B$2:$E$416,4,FALSE) -> 122 | H78: 6.9 | I78: 1.1 | J78: 6.7 | K78: 0.6 | L78: 0 | M78: 0 | N78: 0 | O78: 0 | P78: 0 | Q78: 0 | R78: 0 | S78: 0 | T78: 0 | U78: 0 | V78: 15.3 | W78: 3.8 | X78: 20 | Y78: 1 | Z78: 0 | AA78: 0 | AB78: 0 | AC78: 0 | AD78: 0 | AE78: 0 | AF78: 0 | AG78: 0 | AH78: 0 | AI78: 0
A79: 2025 | B79: Brian Robinson Jr. | C79: SF | D79: {=_xlfn.XLOOKUP(1,('26 WR'!A:A=E79)*('26 WR'!B:B=F79),'26 WR'!C:C)} -> Rachaad White | E79: RB | F79: 38 | G79: =VLOOKUP(B79,[2]FantasyPros_2025_Overall_ADP_Ra!$B$2:$E$416,4,FALSE) -> 128 | H79: 4.7 | I79: 2.9 | J79: 2.2 | K79: 2.1 | L79: 1.2 | M79: 3.8 | N79: 3.6 | O79: 0 | P79: 11.3 | Q79: 11.5 | R79: 2.4 | S79: 5.4 | T79: 2.6 | U79: 0 | V79: 62.5 | W79: 3.7 | X79: 11 | Y79: 1 | Z79: 2 | AA79: 0 | AB79: 0 | AC79: 0 | AD79: 0 | AE79: 0.11764706 | AF79: 0 | AG79: 0 | AH79: 0 | AI79: 0
A80: 2025 | B80: Ollie Gordon II | C80: MIA | D80: {=_xlfn.XLOOKUP(1,('26 WR'!A:A=E80)*('26 WR'!B:B=F80),'26 WR'!C:C)} -> Jacory Croskey-Merritt | E80: RB | F80: 39 | G80: =VLOOKUP(B80,[2]FantasyPros_2025_Overall_ADP_Ra!$B$2:$E$416,4,FALSE) -> 131 | H80: 1.3 | I80: 2.3 | J80: 9.8 | K80: 1 | L80: 0.2 | M80: 1.2 | N80: 2.3 | O80: 13.6 | P80: 1.9 | Q80: 0.3 | R80: 10.5 | S80: 0 | T80: 1 | U80: 7.7 | V80: 54.1 | W80: 3.2 | X80: 11 | Y80: 1 | Z80: 2 | AA80: 0 | AB80: 0 | AC80: 0 | AD80: 0 | AE80: 0.11764706 | AF80: 0 | AG80: 0 | AH80: 0 | AI80: 0
A81: 2025 | B81: Tank Bigsby | C81: PHI | D81: {=_xlfn.XLOOKUP(1,('26 WR'!A:A=E81)*('26 WR'!B:B=F81),'26 WR'!C:C)} -> Tyrone Tracy Jr. | E81: RB | F81: 40 | G81: =VLOOKUP(B81,[2]FantasyPros_2025_Overall_ADP_Ra!$B$2:$E$416,4,FALSE) -> 133 | H81: 1.2 | I81: 0 | J81: 0 | K81: 0 | L81: 0 | M81: 0 | N81: 2 | O81: 10.4 | P81: 0 | Q81: 0.7 | R81: 3.4 | S81: 0.8 | T81: 0 | U81: 0.4 | V81: 53.8 | W81: 3.4 | X81: 12 | Y81: 1 | Z81: 2 | AA81: 1 | AB81: 0 | AC81: 0 | AD81: 0 | AE81: 0.11764706 | AF81: 0.0625 | AG81: 0 | AH81: 0 | AI81: 0
... A170: 2025 | B170: Dawson Knox | C170: BUF | D170: {=_xlfn.XLOOKUP(1,('26 WR'!A:A=E170)*('26 WR'!B:B=F170),'26 WR'!C:C)} -> Theo Johnson | E170: TE | F170: 34 | G170: =VLOOKUP(B170,[2]FantasyPros_2025_Overall_ADP_Ra!$B$2:$E$416,4,FALSE) -> 350 | H170: 4 | I170: 3.9 | J170: 0 | K170: 0 | L170: 3.5 | M170: 8.9 | N170: 0 | O170: 2.5 | P170: 4 | Q170: 6.7 | R170: 3.3 | S170: 4.7 | T170: 5.8 | U170: 17.3 | V170: 103.7 | W170: 6.1 | X170: 20 | Y170: 1 | Z170: 3 | AA170: 2 | AB170: 0 | AC170: 0 | AD170: 0 | AE170: 0.17647059 | AF170: 0.11764706 | AG170: 0 | AH170: 0 | AI170: 0
A171: 2025 | B171: Jake Tonges | C171: SF | D171: {=_xlfn.XLOOKUP(1,('26 WR'!A:A=E171)*('26 WR'!B:B=F171),'26 WR'!C:C)} -> Oscar Delp | E171: TE | F171: 35 | G171: 351 | H171: 10.5 | I171: 7.1 | J171: 4.1 | K171: 14.8 | L171: 17.1 | M171: 11.8 | N171: 0 | O171: 7.2 | P171: 0 | Q171: 0 | R171: 0 | S171: 0 | T171: 0 | U171: 0 | V171: 93.3 | W171: 5.8 | X171: 20 | Y171: 1 | Z171: 5 | AA171: 2 | AB171: 0 | AC171: 0 | AD171: 0 | AE171: 0.29411765 | AF171: 0.125 | AG171: 0 | AH171: 0 | AI171: 0
A172: 2025 | B172: Tommy Tremble | C172: CAR | D172: {=_xlfn.XLOOKUP(1,('26 WR'!A:A=E172)*('26 WR'!B:B=F172),'26 WR'!C:C)} -> Mike Gesicki | E172: TE | F172: 36 | G172: 352 | H172: 1.2 | I172: 5 | J172: 3.6 | K172: 15.2 | L172: 1.7 | M172: 7.9 | N172: 1 | O172: 1.4 | P172: 0 | Q172: 0 | R172: 6.4 | S172: 0 | T172: 1.2 | U172: 0 | V172: 63.9 | W172: 3.8 | X172: 20 | Y172: 1 | Z172: 2 | AA172: 1 | AB172: 0 | AC172: 0 | AD172: 0 | AE172: 0.11764706 | AF172: 0.058823529 | AG172: 0 | AH172: 0 | AI172: 0
A173: 2025 | B173: Davis Allen | C173: LAR | D173: {=_xlfn.XLOOKUP(1,('26 WR'!A:A=E173)*('26 WR'!B:B=F173),'26 WR'!C:C)} -> Greg Dulcich | E173: TE | F173: 37 | G173: 360 | H173: 8.3 | I173: 7.8 | J173: 1.3 | K173: 1 | L173: 4.4 | M173: 1.7 | N173: 1.4 | O173: 0 | P173: 6.7 | Q173: 8.8 | R173: 0 | S173: 5.9 | T173: 1.4 | U173: 4.1 | V173: 62.8 | W173: 3.7 | X173: 20 | Y173: 1 | Z173: 0 | AA173: 0 | AB173: 0 | AC173: 0 | AD173: 0 | AE173: 0 | AF173: 0 | AG173: 0 | AH173: 0 | AI173: 0
A174: 2025 | B174: Cole Kmet | C174: CHI | D174: {=_xlfn.XLOOKUP(1,('26 WR'!A:A=E174)*('26 WR'!B:B=F174),'26 WR'!C:C)} -> Jake Tonges | E174: TE | F174: 38 | G174: =VLOOKUP(B174,[2]FantasyPros_2025_Overall_ADP_Ra!$B$2:$E$416,4,FALSE) -> 365 | H174: 4.1 | I174: 4.9 | J174: 8 | K174: 7.6 | L174: 0 | M174: 1 | N174: 2.6 | O174: 0 | P174: 2 | Q174: 1.5 | R174: 9.5 | S174: 1.3 | T174: 12.6 | U174: 6.2 | V174: 78.7 | W174: 4.9 | X174: 20 | Y174: 1 | Z174: 1 | AA174: 0 | AB174: 0 | AC174: 0 | AD174: 0 | AE174: 0.058823529 | AF174: 0 | AG174: 0 | AH174: 0 | AI174: 0
A175: 2025 | B175: Darnell Washington | C175: PIT | D175: {=_xlfn.XLOOKUP(1,('26 WR'!A:A=E175)*('26 WR'!B:B=F175),'26 WR'!C:C)} -> Darnell Washington | E175: TE | F175: 39 | G175: =VLOOKUP(B175,[2]FantasyPros_2025_Overall_ADP_Ra!$B$2:$E$416,4,FALSE) -> 373 | H175: 0 | I175: 2 | J175: 0 | K175: 5 | L175: 0 | M175: 9.2 | N175: 9.2 | O175: 0 | P175: 8.3 | Q175: 2.5 | R175: 10.7 | S175: 4.2 | T175: 6.5 | U175: 2.2 | V175: 73.4 | W175: 4.6 | X175: 20 | Y175: 1 | Z175: 1 | AA175: 0 | AB175: 0 | AC175: 0 | AD175: 0 | AE175: 0.058823529 | AF175: 0 | AG175: 0 | AH175: 0 | AI175: 0
A176: 2025 | B176: Noah Fant | C176: CIN | D176: {=_xlfn.XLOOKUP(1,('26 WR'!A:A=E176)*('26 WR'!B:B=F176),'26 WR'!C:C)} -> Max Klare | E176: TE | F176: 40 | G176: =VLOOKUP(B176,[2]FantasyPros_2025_Overall_ADP_Ra!$B$2:$E$416,4,FALSE) -> 387 | H176: 12.6 | I176: 5.8 | J176: 5.6 | K176: 0 | L176: 0 | M176: 6.7 | N176: 14.4 | O176: 7.1 | P176: 10.8 | Q176: 0 | R176: 6.6 | S176: 1.9 | T176: 1.3 | U176: 2.5 | V176: 74.8 | W176: 5 | X176: 20 | Y176: 1 | Z176: 3 | AA176: 0 | AB176: 0 | AC176: 0 | AD176: 0 | AE176: 0.17647059 | AF176: 0 | AG176: 0 | AH176: 0 | AI176: 0
A177: 2025 | B177: Gunnar Helm | C177: TEN | D177: {=_xlfn.XLOOKUP(1,('26 WR'!A:A=E177)*('26 WR'!B:B=F177),'26 WR'!C:C)} -> Tyler Higbee | E177: TE | F177: 41 | G177: =VLOOKUP(B177,[2]FantasyPros_2025_Overall_ADP_Ra!$B$2:$E$416,4,FALSE) -> 391 | H177: 2.6 | I177: 2.9 | J177: 5.7 | K177: 2.2 | L177: 7.4 | M177: 3.5 | N177: 7.6 | O177: 10.3 | P177: 2.5 | Q177: 0 | R177: 6.9 | S177: 11.1 | T177: 8.3 | U177: 1.8 | V177: 91.7 | W177: 5.7 | X177: 20 | Y177: 1 | Z177: 3 | AA177: 0 | AB177: 0 | AC177: 0 | AD177: 0 | AE177: 0.17647059 | AF177: 0 | AG177: 0 | AH177: 0 | AI177: 0
A178: 2025 | B178: Greg Dulcich | C178: MIA | D178: {=_xlfn.XLOOKUP(1,('26 WR'!A:A=E178)*('26 WR'!B:B=F178),'26 WR'!C:C)} -> Noah Gray | E178: TE | F178: 42 | G178: =VLOOKUP(B178,[2]FantasyPros_2025_Overall_ADP_Ra!$B$2:$E$416,4,FALSE) -> 407 | H178: 0 | I178: 0 | J178: 0 | K178: 0 | L178: 0 | M178: 0 | N178: 0 | O178: 0 | P178: 9.9 | Q178: 3.2 | R178: 3.8 | S178: 0 | T178: 4.4 | U178: 7.1 | V178: 62.8 | W178: 6.3 | X178: 20 | Y178: 1 | Z178: 1 | AA178: 1 | AB178: 0 | AC178: 0 | AD178: 0 | AE178: 0.058823529 | AF178: 0.1 | AG178: 0 | AH178: 0 | AI178: 0
A179: 2025 | B179: Oronde Gadsden II | C179: LAC | D179: {=_xlfn.XLOOKUP(1,('26 WR'!A:A=E179)*('26 WR'!B:B=F179),'26 WR'!C:C)} -> Elijah Arroyo | E179: TE | F179: 43 | G179: =VLOOKUP(B179,[2]FantasyPros_2025_Overall_ADP_Ra!$B$2:$E$416,4,FALSE) -> 408 | H179: 0 | I179: 0 | J179: 9.6 | K179: 3.6 | L179: 2.4 | M179: 11.8 | N179: 29.4 | O179: 18.7 | P179: 11.8 | Q179: 4.3 | R179: 6.1 | S179: 0 | T179: 3.7 | U179: 1.7 | V179: 131.4 | W179: 8.8 | X179: 20 | Y179: 1 | Z179: 6 | AA179: 2 | AB179: 1 | AC179: 1 | AD179: 0 | AE179: 0.35294118 | AF179: 0.13333333 | AG179: 0.066666667 | AH179: 0.066666667 | AI179: 0
A180: 2025 | B180: Michael Mayer | C180: LV | D180: {=_xlfn.XLOOKUP(1,('26 WR'!A:A=E180)*('26 WR'!B:B=F180),'26 WR'!C:C)} -> Michael Mayer | E180: TE | F180: 44 | G180: =VLOOKUP(B180,[2]FantasyPros_2025_Overall_ADP_Ra!$B$2:$E$416,4,FALSE) -> 410 | H180: 7.8 | I180: 2.9 | J180: 0 | K180: 0 | L180: 0 | M180: 16 | N180: 2 | O180: 0 | P180: 5.6 | Q180: 5.2 | R180: 4.3 | S180: 2.4 | T180: 0 | U180: 0 | V180: 73.8 | W180: 5.7 | X180: 20 | Y180: 1 | Z180: 2 | AA180: 2 | AB180: 0 | AC180: 0 | AD180: 0 | AE180: 0.11764706 | AF180: 0.15384615 | AG180: 0 | AH180: 0 | AI180: 0
A181: 2025 | B181: AJ Barner | C181: SEA | D181: {=_xlfn.XLOOKUP(1,('26 WR'!A:A=E181)*('26 WR'!B:B=F181),'26 WR'!C:C)} -> Ja'Tavion Sanders | E181: TE | F181: 45 | G181: =VLOOKUP(B181,[2]FantasyPros_2025_Overall_ADP_Ra!$B$2:$E$416,4,FALSE) -> 412 | H181: 1.2 | I181: 10.8 | J181: 3.3 | K181: 12.2 | L181: 24.3 | M181: 10.1 | N181: 1.9 | O181: 0 | P181: 11.5 | Q181: 0.3 | R181: 17.1 | S181: 3.8 | T181: 7.7 | U181: 5.7 | V181: 147.3 | W181: 8.7 | X181: 20 | Y181: 1 | Z181: 8 | AA181: 2 | AB181: 1 | AC181: 0 | AD181: 0 | AE181: 0.47058824 | AF181: 0.11764706 | AG181: 0.058823529 | AH181: 0 | AI181: 0
A182: 2025 | B182: Ja'Marr Chase | C182: CIN | D182: {=_xlfn.XLOOKUP(1,('26 WR'!A:A=E182)*('26 WR'!B:B=F182),'26 WR'!C:C)} -> Ja'Marr Chase | E182: WR | F182: 1 | G182: =VLOOKUP(B182,[2]FantasyPros_2025_Overall_ADP_Ra!$B$2:$E$416,4,FALSE) -> 1 | H182: 4.6 | I182: 36.5 | J182: 8.9 | K182: 7.3 | L182: 29 | M182: 25.1 | N182: 38.1 | O182: 21.1 | P182: 17.1 | Q182: 0 | R182: 6 | S182: 0 | T182: 18 | U182: 10.2 | V182: 313.6 | W182: 19.6 | X182: 1 | Y182: 1 | Z182: 12 | AA182: 11 | AB182: 8 | AC182: 4 | AD182: 2 | AE182: 0.70588235 | AF182: 0.6875 | AG182: 0.5 | AH182: 0.25 | AI182: 0.125
...

Sheet FFPC Best Ball
A1: Year | B1: 2025 Player | C1: Team | D1: Player | E1: Position | F1: POS Rank | G1: ADP | H1: 1 | I1: 2 | J1: 3 | K1: 4 | L1: 5 | M1: 6 | N1: 7 | O1: 8 | P1: 9 | Q1: 10 | R1: 11 | S1: 12 | T1: 13 | U1: 14 | V1: 15 | W1: 16 | X1: 17 | Y1: TTL | Z1: AVG | AA1: Round | AB1: Position Pick | AC1: Boom 10 | AD1: Boom 15 | AE1: Boom 20 | AF1: Boom 25 | AG1: Boom 30 | AH1: Boom 10% | AI1: Boom 15% | AJ1: Boom 20% | AK1: Boom 25% | AL1: Boom 30%
A2: 2025 | B2: Josh Allen | C2: BUF | D2: {=_xlfn.XLOOKUP(1,('26 WR'!A:A=E2)*('26 WR'!B:B=F2),'26 WR'!C:C)} -> Josh Allen | E2: QB | F2: 1 | G2: 26 | H2: 38.8 | I2: 11.8 | J2: 23 | K2: 25.9 | L2: 20.4 | M2: 17.4 | N2: 0 | O2: 23.2 | P2: 28.8 | Q2: 20.3 | R2: 44.7 | S2: 10.1 | T2: 17.7 | U2: 37.8 | V2: 24.5 | W2: 6.9 | X2: 23.2 | Y2: 374.5 | Z2: 22 | AA2: 1 | AB2: 1 | AC2: 15 | AD2: 13 | AE2: 11 | AF2: 5 | AG2: 3 | AH2: 0.88235294 | AI2: 0.76470588 | AJ2: 0.64705882 | AK2: 0.29411765 | AL2: 0.17647059
A3: 2025 | B3: Lamar Jackson | C3: BAL | D3: {=_xlfn.XLOOKUP(1,('26 WR'!A:A=E3)*('26 WR'!B:B=F3),'26 WR'!C:C)} -> Lamar Jackson | E3: QB | F3: 2 | G3: 28 | H3: 29.4 | I3: 26.3 | J3: 27 | K3: 11.7 | L3: 0 | M3: 0 | N3: 0 | O3: 0 | P3: 25.6 | Q3: 16.6 | R3: 6.7 | S3: 7.2 | T3: 7.5 | U3: 22.1 | V3: 15.6 | W3: 4.7 | X3: 0 | Y3: 200.4 | Z3: 17.1 | AA3: 20 | AB3: 1 | AC3: 9 | AD3: 8 | AE3: 6 | AF3: 4 | AG3: 0 | AH3: 0.52941176 | AI3: 0.61538462 | AJ3: 0.46153846 | AK3: 0.30769231 | AL3: 0
A4: 2025 | B4: Jayden Daniels | C4: WAS | D4: {=_xlfn.XLOOKUP(1,('26 WR'!A:A=E4)*('26 WR'!B:B=F4),'26 WR'!C:C)} -> Drake Maye | E4: QB | F4: 3 | G4: 35 | H4: 20.1 | I4: 19.7 | J4: 0 | K4: 0 | L4: 17.1 | M4: 22.6 | N4: 17.7 | O4: 0 | P4: 16.2 | Q4: 0 | R4: 0 | S4: 0 | T4: 0 | U4: 3.7 | V4: 0 | W4: 0 | X4: 0 | Y4: 117.1 | Z4: 16.8 | AA4: 34 | AB4: 1 | AC4: 6 | AD4: 6 | AE4: 2 | AF4: 0 | AG4: 0 | AH4: 0.35294118 | AI4: 0.85714286 | AJ4: 0.28571429 | AK4: 0 | AL4: 0
A5: 2025 | B5: Jalen Hurts | C5: PHI | D5: {=_xlfn.XLOOKUP(1,('26 WR'!A:A=E5)*('26 WR'!B:B=F5),'26 WR'!C:C)} -> Joe Burrow | E5: QB | F5: 4 | G5: 42 | H5: 24.3 | I5: 11.5 | J5: 29 | K5: 19.4 | L5: 19.5 | M5: 21.6 | N5: 24 | O5: 25.4 | P5: 0 | Q5: 12 | R5: 14.5 | S5: 30.9 | T5: 17.3 | U5: 4.4 | V5: 22.9 | W5: 19.4 | X5: 8.9 | Y5: 305 | Z5: 19.1 | AA5: 9 | AB5: 1 | AC5: 14 | AD5: 11 | AE5: 7 | AF5: 3 | AG5: 1 | AH5: 0.82352941 | AI5: 0.6875 | AJ5: 0.4375 | AK5: 0.1875 | AL5: 0.0625
A6: 2025 | B6: Joe Burrow | C6: CIN | D6: {=_xlfn.XLOOKUP(1,('26 WR'!A:A=E6)*('26 WR'!B:B=F6),'26 WR'!C:C)} -> Jayden Daniels | E6: QB | F6: 5 | G6: 45 | H6: 8.8 | I6: 7 | J6: 0 | K6: 0 | L6: 0 | M6: 0 | N6: 0 | O6: 0 | P6: 0 | Q6: 0 | R6: 0 | S6: 0 | T6: 19.2 | U6: 25.4 | V6: 7.5 | W6: 29 | X6: 20.4 | Y6: 117.3 | Z6: 17.4 | AA6: 7 | AB6: 1 | AC6: 5 | AD6: 5 | AE6: 4 | AF6: 2 | AG6: 0 | AH6: 0.29411765 | AI6: 0.625 | AJ6: 0.5 | AK6: 0.25 | AL6: 0
A7: 2025 | B7: Patrick Mahomes II | C7: KC | D7: {=_xlfn.XLOOKUP(1,('26 WR'!A:A=E7)*('26 WR'!B:B=F7),'26 WR'!C:C)} -> Jalen Hurts | E7: QB | F7: 6 | G7: 76 | H7: 26 | I7: 23.1 | J7: 13.2 | K7: 27.3 | L7: 27.7 | M7: 31.5 | N7: 26.2 | O7: 25 | P7: 11.5 | Q7: 0 | R7: 14.3 | S7: 18.1 | T7: 29.4 | U7: 8.3 | V7: 14.1 | W7: 0 | X7: 0 | Y7: 295.7 | Z7: 21.1 | AA7: 11 | AB7: 1 | AC7: 13 | AD7: 9 | AE7: 8 | AF7: 6 | AG7: 1 | AH7: 0.76470588 | AI7: 0.64285714 | AJ7: 0.57142857 | AK7: 0.42857143 | AL7: 0.071428571
A8: 2025 | B8: Baker Mayfield | C8: TB | D8: {=_xlfn.XLOOKUP(1,('26 WR'!A:A=E8)*('26 WR'!B:B=F8),'26 WR'!C:C)} -> Caleb Williams | E8: QB | F8: 7 | G8: 84 | H8: 22.6 | I8: 19.9 | J8: 17.7 | K8: 19.9 | L8: 26.7 | M8: 19.6 | N8: 12.1 | O8: 4.1 | P8: 0 | Q8: 22.9 | R8: 17.8 | S8: 5.5 | T8: 14.5 | U8: 12.1 | V8: 20.2 | W8: 13.7 | X8: 19.4 | Y8: 268.7 | Z8: 16.6 | AA8: 12 | AB8: 1 | AC8: 15 | AD8: 10 | AE8: 4 | AF8: 1 | AG8: 0 | AH8: 0.88235294 | AI8: 0.58823529 | AJ8: 0.23529412 | AK8: 0.058823529 | AL8: 0
A9: 2025 | B9: Justin Fields | C9: NYJ | D9: {=_xlfn.XLOOKUP(1,('26 WR'!A:A=E9)*('26 WR'!B:B=F9),'26 WR'!C:C)} -> Justin Herbert | E9: QB | F9: 8 | G9: 89 | H9: 29.5 | I9: 4 | J9: 0 | K9: 27.1 | L9: 25.9 | M9: 4.9 | N9: 4 | O9: 20.9 | P9: 0 | Q9: 8 | R9: 19.3 | S9: 0 | T9: 0 | U9: 0 | V9: 0 | W9: 0 | X9: 0 | Y9: 143.6 | Z9: 16 | AA9: 10 | AB9: 1 | AC9: 5 | AD9: 5 | AE9: 4 | AF9: 3 | AG9: 0 | AH9: 0.29411765 | AI9: 0.55555556 | AJ9: 0.44444444 | AK9: 0.33333333 | AL9: 0
A10: 2025 | B10: Bo Nix | C10: DEN | D10: {=_xlfn.XLOOKUP(1,('26 WR'!A:A=E10)*('26 WR'!B:B=F10),'26 WR'!C:C)} -> Trevor Lawrence | E10: QB | F10: 9 | G10: 90 | H10: 8.8 | I10: 21.2 | J10: 13.4 | K10: 26.7 | L10: 17.9 | M10: 13.4 | N10: 40 | O10: 24.8 | P10: 19.5 | Q10: 7.8 | R10: 12.6 | S10: 0 | T10: 17.4 | U10: 16 | V10: 29.1 | W10: 16.2 | X10: 20.5 | Y10: 305.3 | Z10: 18.6 | AA10: 7 | AB10: 1 | AC10: 15 | AD10: 11 | AE10: 6 | AF10: 3 | AG10: 1 | AH10: 0.88235294 | AI10: 0.64705882 | AJ10: 0.35294118 | AK10: 0.17647059 | AL10: 0.058823529
A11: 2025 | B11: Dak Prescott | C11: DAL | D11: {=_xlfn.XLOOKUP(1,('26 WR'!A:A=E11)*('26 WR'!B:B=F11),'26 WR'!C:C)} -> Dak Prescott | E11: QB | F11: 10 | G11: 93 | H11: 7.8 | I11: 23.1 | J11: 14 | K11: 31 | L11: 28.3 | M11: 22.3 | N11: 23.3 | O11: 8.6 | P11: 16.4 | Q11: 0 | R11: 24.3 | S11: 28.1 | T11: 21.6 | U11: 20.4 | V11: 12 | W11: 19.2 | X11: 22.7 | Y11: 323.1 | Z11: 19 | AA11: 5 | AB11: 1 | AC11: 14 | AD11: 12 | AE11: 10 | AF11: 3 | AG11: 1 | AH11: 0.82352941 | AI11: 0.70588235 | AJ11: 0.58823529 | AK11: 0.17647059 | AL11: 0.058823529
A12: 2025 | B12: Kyler Murray | C12: ARI | D12: {=_xlfn.XLOOKUP(1,('26 WR'!A:A=E12)*('26 WR'!B:B=F12),'26 WR'!C:C)} -> Jaxson Dart | E12: QB | F12: 11 | G12: 104 | H12: 18.3 | I12: 15 | J12: 14.1 | K12: 18.1 | L12: 15.3 | M12: 0 | N12: 0 | O12: 0 | P12: 0 | Q12: 0 | R12: 0 | S12: 0 | T12: 0 | U12: 0 | V12: 0 | W12: 0 | X12: 0 | Y12: 80.8 | Z12: 16.2 | AA12: 38 | AB12: 1 | AC12: 5 | AD12: 3 | AE12: 0 | AF12: 0 | AG12: 0 | AH12: 0.29411765 | AI12: 0.6 | AJ12: 0 | AK12: 0 | AL12: 0
A13: 2025 | B13: Caleb Williams | C13: CHI | D13: {=_xlfn.XLOOKUP(1,('26 WR'!A:A=E13)*('26 WR'!B:B=F13),'26 WR'!C:C)} -> Brock Purdy | E13: QB | F13: 12 | G13: 107 | H13: 24.2 | I13: 18 | J13: 29.1 | K13: 12.8 | L13: 0 | M13: 19.9 | N13: 5.7 | O13: 12.8 | P13: 36.7 | Q13: 25.1 | R13: 10.3 | S13: 21.7 | T13: 10.5 | U13: 15.9 | V13: 19 | W13: 21 | X13: 23 | Y13: 305.7 | Z13: 19 | AA13: 6 | AB13: 1 | AC13: 16 | AD13: 12 | AE13: 7 | AF13: 3 | AG13: 1 | AH13: 0.94117647 | AI13: 0.70588235 | AJ13: 0.41176471 | AK13: 0.17647059 | AL13: 0.058823529
... A300: 2025 | B300: Isaiah Williams | C300: NYJ | D300: {=_xlfn.XLOOKUP(1,('26 WR'!A:A=E300)*('26 WR'!B:B=F300),'26 WR'!C:C)} -> Jahan Dotson | E300: WR | F300: 119 | G300: 299 | H300: 0 | I300: 0 | J300: 0 | K300: 2 | L300: 0 | M300: 0 | N300: 0 | O300: 8.6 | P300: 0 | Q300: 7.4 | R300: 1.6 | S300: 0 | T300: 0 | U300: 10.4 | V300: 11.3 | W300: 6.5 | X300: 7.5 | Y300: 55.3 | Z300: 3.9 | AA300: 20 | AB300: 1 | AC300: 2 | AD300: 0 | AE300: 0 | AF300: 0 | AG300: 0 | AH300: 0.11764706 | AI300: 0 | AJ300: 0 | AK300: 0 | AL300: 0

Sheet FFPC Super Best Ball
A1: Year | B1: 2025 Player | C1: Team | D1: Player | E1: Position | F1: POS Rank | G1: ADP | H1: 1 | I1: 2 | J1: 3 | K1: 4 | L1: 5 | M1: 6 | N1: 7 | O1: 8 | P1: 9 | Q1: 10 | R1: 11 | S1: 12 | T1: 13 | U1: 14 | V1: 15 | W1: 16 | X1: 17 | Y1: TTL | Z1: AVG | AA1: Round | AB1: Position Pick | AC1: Boom 10 | AD1: Boom 15 | AE1: Boom 20 | AF1: Boom 25 | AG1: Boom 30 | AH1: Boom 10% | AI1: Boom 15% | AJ1: Boom 20% | AK1: Boom 25% | AL1: Boom 30%
A2: 2025 | B2: Josh Allen | C2: BUF | D2: {=_xlfn.XLOOKUP(1,('26 WR'!A:A=E2)*('26 WR'!B:B=F2),'26 WR'!C:C)} -> Josh Allen | E2: QB | F2: 1 | G2: 2 | H2: 38.8 | I2: 11.8 | J2: 23 | K2: 25.9 | L2: 20.4 | M2: 17.4 | N2: 0 | O2: 23.2 | P2: 28.8 | Q2: 20.3 | R2: 44.7 | S2: 10.1 | T2: 17.7 | U2: 37.8 | V2: 24.5 | W2: 6.9 | X2: 23.2 | Y2: =SUM(H2:X2) -> 374.5 | Z2: 22 | AA2: 1 | AB2: 1 | AC2: 15 | AD2: 13 | AE2: 11 | AF2: 5 | AG2: 3 | AH2: 0.88235294 | AI2: 0.76470588 | AJ2: 0.64705882 | AK2: 0.29411765 | AL2: 0.17647059
A3: 2025 | B3: Lamar Jackson | C3: BAL | D3: {=_xlfn.XLOOKUP(1,('26 WR'!A:A=E3)*('26 WR'!B:B=F3),'26 WR'!C:C)} -> Lamar Jackson | E3: QB | F3: 2 | G3: 5 | H3: 29.4 | I3: 26.3 | J3: 27 | K3: 11.7 | L3: 0 | M3: 0 | N3: 0 | O3: 0 | P3: 25.6 | Q3: 16.6 | R3: 6.7 | S3: 7.2 | T3: 7.5 | U3: 22.1 | V3: 15.6 | W3: 4.7 | X3: 0 | Y3: =SUM(H3:X3) -> 200.4 | Z3: 17.1 | AA3: 20 | AB3: 1 | AC3: 9 | AD3: 8 | AE3: 6 | AF3: 4 | AG3: 0 | AH3: 0.52941176 | AI3: 0.61538462 | AJ3: 0.46153846 | AK3: 0.30769231 | AL3: 0
A4: 2025 | B4: Jayden Daniels | C4: WAS | D4: {=_xlfn.XLOOKUP(1,('26 WR'!A:A=E4)*('26 WR'!B:B=F4),'26 WR'!C:C)} -> Drake Maye | E4: QB | F4: 3 | G4: 11 | H4: 20.1 | I4: 19.7 | J4: 0 | K4: 0 | L4: 17.1 | M4: 22.6 | N4: 17.7 | O4: 0 | P4: 16.2 | Q4: 0 | R4: 0 | S4: 0 | T4: 0 | U4: 3.7 | V4: 0 | W4: 0 | X4: 0 | Y4: =SUM(H4:X4) -> 117.1 | Z4: 16.8 | AA4: 34 | AB4: 1 | AC4: 6 | AD4: 6 | AE4: 2 | AF4: 0 | AG4: 0 | AH4: 0.35294118 | AI4: 0.85714286 | AJ4: 0.28571429 | AK4: 0 | AL4: 0
A5: 2025 | B5: Jalen Hurts | C5: PHI | D5: {=_xlfn.XLOOKUP(1,('26 WR'!A:A=E5)*('26 WR'!B:B=F5),'26 WR'!C:C)} -> Joe Burrow | E5: QB | F5: 4 | G5: 14 | H5: 24.3 | I5: 11.5 | J5: 29 | K5: 19.4 | L5: 19.5 | M5: 21.6 | N5: 24 | O5: 25.4 | P5: 0 | Q5: 12 | R5: 14.5 | S5: 30.9 | T5: 17.3 | U5: 4.4 | V5: 22.9 | W5: 19.4 | X5: 8.9 | Y5: =SUM(H5:X5) -> 305 | Z5: 19.1 | AA5: 9 | AB5: 1 | AC5: 14 | AD5: 11 | AE5: 7 | AF5: 3 | AG5: 1 | AH5: 0.82352941 | AI5: 0.6875 | AJ5: 0.4375 | AK5: 0.1875 | AL5: 0.0625
A6: 2025 | B6: Joe Burrow | C6: CIN | D6: {=_xlfn.XLOOKUP(1,('26 WR'!A:A=E6)*('26 WR'!B:B=F6),'26 WR'!C:C)} -> Jayden Daniels | E6: QB | F6: 5 | G6: 16 | H6: 8.8 | I6: 7 | J6: 0 | K6: 0 | L6: 0 | M6: 0 | N6: 0 | O6: 0 | P6: 0 | Q6: 0 | R6: 0 | S6: 0 | T6: 19.2 | U6: 25.4 | V6: 7.5 | W6: 29 | X6: 20.4 | Y6: =SUM(H6:X6) -> 117.3 | Z6: 17.4 | AA6: 7 | AB6: 1 | AC6: 5 | AD6: 5 | AE6: 4 | AF6: 2 | AG6: 0 | AH6: 0.29411765 | AI6: 0.625 | AJ6: 0.5 | AK6: 0.25 | AL6: 0
A7: 2025 | B7: Patrick Mahomes II | C7: KC | D7: {=_xlfn.XLOOKUP(1,('26 WR'!A:A=E7)*('26 WR'!B:B=F7),'26 WR'!C:C)} -> Jalen Hurts | E7: QB | F7: 6 | G7: 19 | H7: 26 | I7: 23.1 | J7: 13.2 | K7: 27.3 | L7: 27.7 | M7: 31.5 | N7: 26.2 | O7: 25 | P7: 11.5 | Q7: 0 | R7: 14.3 | S7: 18.1 | T7: 29.4 | U7: 8.3 | V7: 14.1 | W7: 0 | X7: 0 | Y7: =SUM(H7:X7) -> 295.7 | Z7: 21.1 | AA7: 11 | AB7: 1 | AC7: 13 | AD7: 9 | AE7: 8 | AF7: 6 | AG7: 1 | AH7: 0.76470588 | AI7: 0.64285714 | AJ7: 0.57142857 | AK7: 0.42857143 | AL7: 0.071428571
A8: 2025 | B8: Baker Mayfield | C8: TB | D8: {=_xlfn.XLOOKUP(1,('26 WR'!A:A=E8)*('26 WR'!B:B=F8),'26 WR'!C:C)} -> Caleb Williams | E8: QB | F8: 7 | G8: 29 | H8: 22.6 | I8: 19.9 | J8: 17.7 | K8: 19.9 | L8: 26.7 | M8: 19.6 | N8: 12.1 | O8: 4.1 | P8: 0 | Q8: 22.9 | R8: 17.8 | S8: 5.5 | T8: 14.5 | U8: 12.1 | V8: 20.2 | W8: 13.7 | X8: 19.4 | Y8: =SUM(H8:X8) -> 268.7 | Z8: 16.6 | AA8: 12 | AB8: 1 | AC8: 15 | AD8: 10 | AE8: 4 | AF8: 1 | AG8: 0 | AH8: 0.88235294 | AI8: 0.58823529 | AJ8: 0.23529412 | AK8: 0.058823529 | AL8: 0
A9: 2025 | B9: Justin Fields | C9: NYJ | D9: {=_xlfn.XLOOKUP(1,('26 WR'!A:A=E9)*('26 WR'!B:B=F9),'26 WR'!C:C)} -> Justin Herbert | E9: QB | F9: 8 | G9: 32 | H9: 29.5 | I9: 4 | J9: 0 | K9: 27.1 | L9: 25.9 | M9: 4.9 | N9: 4 | O9: 20.9 | P9: 0 | Q9: 8 | R9: 19.3 | S9: 0 | T9: 0 | U9: 0 | V9: 0 | W9: 0 | X9: 0 | Y9: =SUM(H9:X9) -> 143.6 | Z9: 16 | AA9: 10 | AB9: 1 | AC9: 5 | AD9: 5 | AE9: 4 | AF9: 3 | AG9: 0 | AH9: 0.29411765 | AI9: 0.55555556 | AJ9: 0.44444444 | AK9: 0.33333333 | AL9: 0
A10: 2025 | B10: Bo Nix | C10: DEN | D10: {=_xlfn.XLOOKUP(1,('26 WR'!A:A=E10)*('26 WR'!B:B=F10),'26 WR'!C:C)} -> Trevor Lawrence | E10: QB | F10: 9 | G10: 34 | H10: 8.8 | I10: 21.2 | J10: 13.4 | K10: 26.7 | L10: 17.9 | M10: 13.4 | N10: 40 | O10: 24.8 | P10: 19.5 | Q10: 7.8 | R10: 12.6 | S10: 0 | T10: 17.4 | U10: 16 | V10: 29.1 | W10: 16.2 | X10: 20.5 | Y10: =SUM(H10:X10) -> 305.3 | Z10: 18.6 | AA10: 7 | AB10: 1 | AC10: 15 | AD10: 11 | AE10: 6 | AF10: 3 | AG10: 1 | AH10: 0.88235294 | AI10: 0.64705882 | AJ10: 0.35294118 | AK10: 0.17647059 | AL10: 0.058823529
A11: 2025 | B11: Dak Prescott | C11: DAL | D11: {=_xlfn.XLOOKUP(1,('26 WR'!A:A=E11)*('26 WR'!B:B=F11),'26 WR'!C:C)} -> Dak Prescott | E11: QB | F11: 10 | G11: 36 | H11: 7.8 | I11: 23.1 | J11: 14 | K11: 31 | L11: 28.3 | M11: 22.3 | N11: 23.3 | O11: 8.6 | P11: 16.4 | Q11: 0 | R11: 24.3 | S11: 28.1 | T11: 21.6 | U11: 20.4 | V11: 12 | W11: 19.2 | X11: 22.7 | Y11: =SUM(H11:X11) -> 323.1 | Z11: 19 | AA11: 5 | AB11: 1 | AC11: 14 | AD11: 12 | AE11: 10 | AF11: 3 | AG11: 1 | AH11: 0.82352941 | AI11: 0.70588235 | AJ11: 0.58823529 | AK11: 0.17647059 | AL11: 0.058823529
A12: 2025 | B12: Kyler Murray | C12: ARI | D12: {=_xlfn.XLOOKUP(1,('26 WR'!A:A=E12)*('26 WR'!B:B=F12),'26 WR'!C:C)} -> Jaxson Dart | E12: QB | F12: 11 | G12: 39 | H12: 18.3 | I12: 15 | J12: 14.1 | K12: 18.1 | L12: 15.3 | M12: 0 | N12: 0 | O12: 0 | P12: 0 | Q12: 0 | R12: 0 | S12: 0 | T12: 0 | U12: 0 | V12: 0 | W12: 0 | X12: 0 | Y12: =SUM(H12:X12) -> 80.8 | Z12: 16.2 | AA12: 38 | AB12: 1 | AC12: 5 | AD12: 3 | AE12: 0 | AF12: 0 | AG12: 0 | AH12: 0.29411765 | AI12: 0.6 | AJ12: 0 | AK12: 0 | AL12: 0
A13: 2025 | B13: Caleb Williams | C13: CHI | D13: {=_xlfn.XLOOKUP(1,('26 WR'!A:A=E13)*('26 WR'!B:B=F13),'26 WR'!C:C)} -> Brock Purdy | E13: QB | F13: 12 | G13: 41 | H13: 24.2 | I13: 18 | J13: 29.1 | K13: 12.8 | L13: 0 | M13: 19.9 | N13: 5.7 | O13: 12.8 | P13: 36.7 | Q13: 25.1 | R13: 10.3 | S13: 21.7 | T13: 10.5 | U13: 15.9 | V13: 19 | W13: 21 | X13: 23 | Y13: =SUM(H13:X13) -> 305.7 | Z13: 19 | AA13: 6 | AB13: 1 | AC13: 16 | AD13: 12 | AE13: 7 | AF13: 3 | AG13: 1 | AH13: 0.94117647 | AI13: 0.70588235 | AJ13: 0.41176471 | AK13: 0.17647059 | AL13: 0.058823529
... A136: 2025 | B136: Phil Mafah | C136: DAL | D136: {=_xlfn.XLOOKUP(1,('26 WR'!A:A=E136)*('26 WR'!B:B=F136),'26 WR'!C:C)} -> Isaac Guerendo | E136: RB | F136: 95 | G136: 298 | H136: 0 | I136: 0 | J136: 0 | K136: 0 | L136: 0 | M136: 0 | N136: 0 | O136: 0 | P136: 0 | Q136: 0 | R136: 0 | S136: 0 | T136: 0 | U136: 0 | V136: 0 | W136: 0 | X136: 0 | Y136: =SUM(H136:X136) -> 0 | Z136: 10.9 | AA136: 20 | AB136: 1 | AC136: 1 | AD136: 0 | AE136: 0 | AF136: 0 | AG136: 0 | AH136: 0.058823529 | AI136: 0 | AJ136: 0 | AK136: 0 | AL136: 0
A137: 2025 | B137: Brock Bowers | C137: LV | D137: {=_xlfn.XLOOKUP(1,('26 WR'!A:A=E137)*('26 WR'!B:B=F137),'26 WR'!C:C)} -> Trey McBride | E137: TE | F137: 1 | G137: 6 | H137: =_xlfn.XLOOKUP($B137,'[1]FFPC TE'!$A$2:$A$46,'[1]FFPC TE'!B$2:B$46,,0) -> 17.8 | I137: =_xlfn.XLOOKUP($B137,'[1]FFPC TE'!$A$2:$A$46,'[1]FFPC TE'!C$2:C$46,,0) -> 11.3 | J137: =_xlfn.XLOOKUP($B137,'[1]FFPC TE'!$A$2:$A$46,'[1]FFPC TE'!D$2:D$46,,0) -> 9.8 | K137: =_xlfn.XLOOKUP($B137,'[1]FFPC TE'!$A$2:$A$46,'[1]FFPC TE'!E$2:E$46,,0) -> 12.1 | L137: =_xlfn.XLOOKUP($B137,'[1]FFPC TE'!$A$2:$A$46,'[1]FFPC TE'!F$2:F$46,,0) -> 0 | M137: =_xlfn.XLOOKUP($B137,'[1]FFPC TE'!$A$2:$A$46,'[1]FFPC TE'!G$2:G$46,,0) -> 0 | N137: =_xlfn.XLOOKUP($B137,'[1]FFPC TE'!$A$2:$A$46,'[1]FFPC TE'!H$2:H$46,,0) -> 0 | O137: =_xlfn.XLOOKUP($B137,'[1]FFPC TE'!$A$2:$A$46,'[1]FFPC TE'!I$2:I$46,,0) -> 0 | ... X137: =_xlfn.XLOOKUP($B137,'[1]FFPC TE'!$A$2:$A$46,'[1]FFPC TE'!R$2:R$46,,0) -> 0 | Y137: =SUM(H137:X137) -> 206 | Z137: 14.7 | AA137: 2 | AB137: 1 | AC137: 7 | AD137: 3 | AE137: 2 | AF137: 1 | AG137: 1 | AH137: 0.41176471 | AI137: 0.25 | AJ137: 0.16666667 | AK137: 0.083333333 | AL137: 0.083333333
A138: 2025 | B138: Trey McBride | C138: ARI | D138: {=_xlfn.XLOOKUP(1,('26 WR'!A:A=E138)*('26 WR'!B:B=F138),'26 WR'!C:C)} -> Brock Bowers | E138: TE | F138: 2 | G138: 17 | H138: =_xlfn.XLOOKUP($B138,'[1]FFPC TE'!$A$2:$A$46,'[1]FFPC TE'!B$2:B$46,,0) -> 15.1 | I138: =_xlfn.XLOOKUP($B138,'[1]FFPC TE'!$A$2:$A$46,'[1]FFPC TE'!C$2:C$46,,0) -> 16.8 | J138: =_xlfn.XLOOKUP($B138,'[1]FFPC TE'!$A$2:$A$46,'[1]FFPC TE'!D$2:D$46,,0) -> 17.8 | K138: =_xlfn.XLOOKUP($B138,'[1]FFPC TE'!$A$2:$A$46,'[1]FFPC TE'!E$2:E$46,,0) -> 15.7 | L138: =_xlfn.XLOOKUP($B138,'[1]FFPC TE'!$A$2:$A$46,'[1]FFPC TE'!F$2:F$46,,0) -> 11.6 | M138: =_xlfn.XLOOKUP($B138,'[1]FFPC TE'!$A$2:$A$46,'[1]FFPC TE'!G$2:G$46,,0) -> 25.2 | N138: =_xlfn.XLOOKUP($B138,'[1]FFPC TE'!$A$2:$A$46,'[1]FFPC TE'!H$2:H$46,,0) -> 34.4 | O138: =_xlfn.XLOOKUP($B138,'[1]FFPC TE'!$A$2:$A$46,'[1]FFPC TE'!I$2:I$46,,0) -> 0 | ... X138: =_xlfn.XLOOKUP($B138,'[1]FFPC TE'!$A$2:$A$46,'[1]FFPC TE'!R$2:R$46,,0) -> 28.6 | Y138: =SUM(H138:X138) -> 361.9 | Z138: 18.6 | AA138: 3 | AB138: 1 | AC138: 15 | AD138: 10 | AE138: 7 | AF138: 4 | AG138: 1 | AH138: 0.88235294 | AI138: 0.58823529 | AJ138: 0.41176471 | AK138: 0.23529412 | AL138: 0.058823529
A139: 2025 | B139: George Kittle | C139: SF | D139: {=_xlfn.XLOOKUP(1,('26 WR'!A:A=E139)*('26 WR'!B:B=F139),'26 WR'!C:C)} -> Colston Loveland | E139: TE | F139: 3 | G139: 31 | H139: =_xlfn.XLOOKUP($B139,'[1]FFPC TE'!$A$2:$A$46,'[1]FFPC TE'!B$2:B$46,,0) -> 14.5 | I139: =_xlfn.XLOOKUP($B139,'[1]FFPC TE'!$A$2:$A$46,'[1]FFPC TE'!C$2:C$46,,0) -> 0 | J139: =_xlfn.XLOOKUP($B139,'[1]FFPC TE'!$A$2:$A$46,'[1]FFPC TE'!D$2:D$46,,0) -> 0 | K139: =_xlfn.XLOOKUP($B139,'[1]FFPC TE'!$A$2:$A$46,'[1]FFPC TE'!E$2:E$46,,0) -> 0 | L139: =_xlfn.XLOOKUP($B139,'[1]FFPC TE'!$A$2:$A$46,'[1]FFPC TE'!F$2:F$46,,0) -> 0 | M139: =_xlfn.XLOOKUP($B139,'[1]FFPC TE'!$A$2:$A$46,'[1]FFPC TE'!G$2:G$46,,0) -> 0 | N139: =_xlfn.XLOOKUP($B139,'[1]FFPC TE'!$A$2:$A$46,'[1]FFPC TE'!H$2:H$46,,0) -> 0 | O139: =_xlfn.XLOOKUP($B139,'[1]FFPC TE'!$A$2:$A$46,'[1]FFPC TE'!I$2:I$46,,0) -> 16.3 | ... X139: =_xlfn.XLOOKUP($B139,'[1]FFPC TE'!$A$2:$A$46,'[1]FFPC TE'!R$2:R$46,,0) -> 0 | Y139: =SUM(H139:X139) -> 179.9 | Z139: 14.7 | AA139: 3 | AB139: 1 | AC139: 8 | AD139: 4 | AE139: 4 | AF139: 0 | AG139: 0 | AH139: 0.47058824 | AI139: 0.36363636 | AJ139: 0.36363636 | AK139: 0 | AL139: 0
A140: 2025 | B140: Sam LaPorta | C140: DET | D140: {=_xlfn.XLOOKUP(1,('26 WR'!A:A=E140)*('26 WR'!B:B=F140),'26 WR'!C:C)} -> Tyler Warren | E140: TE | F140: 4 | G140: 55 | H140: =_xlfn.XLOOKUP($B140,'[1]FFPC TE'!$A$2:$A$46,'[1]FFPC TE'!B$2:B$46,,0) -> 16.9 | I140: =_xlfn.XLOOKUP($B140,'[1]FFPC TE'!$A$2:$A$46,'[1]FFPC TE'!C$2:C$46,,0) -> 7.1 | J140: =_xlfn.XLOOKUP($B140,'[1]FFPC TE'!$A$2:$A$46,'[1]FFPC TE'!D$2:D$46,,0) -> 9.3 | K140: =_xlfn.XLOOKUP($B140,'[1]FFPC TE'!$A$2:$A$46,'[1]FFPC TE'!E$2:E$46,,0) -> 8.4 | L140: =_xlfn.XLOOKUP($B140,'[1]FFPC TE'!$A$2:$A$46,'[1]FFPC TE'!F$2:F$46,,0) -> 22.7 | M140: =_xlfn.XLOOKUP($B140,'[1]FFPC TE'!$A$2:$A$46,'[1]FFPC TE'!G$2:G$46,,0) -> 19 | N140: =_xlfn.XLOOKUP($B140,'[1]FFPC TE'!$A$2:$A$46,'[1]FFPC TE'!H$2:H$46,,0) -> 6 | O140: =_xlfn.XLOOKUP($B140,'[1]FFPC TE'!$A$2:$A$46,'[1]FFPC TE'!I$2:I$46,,0) -> 0 | ... X140: =_xlfn.XLOOKUP($B140,'[1]FFPC TE'!$A$2:$A$46,'[1]FFPC TE'!R$2:R$46,,0) -> 0 | Y140: =SUM(H140:X140) -> 126.9 | Z140: 11.9 | AA140: 6 | AB140: 1 | AC140: 5 | AD140: 3 | AE140: 2 | AF140: 0 | AG140: 0 | AH140: 0.29411765 | AI140: 0.33333333 | AJ140: 0.22222222 | AK140: 0 | AL140: 0
A141: 2025 | B141: Travis Kelce | C141: KC | D141: {=_xlfn.XLOOKUP(1,('26 WR'!A:A=E141)*('26 WR'!B:B=F141),'26 WR'!C:C)} -> Harold Fannin Jr. | E141: TE | F141: 5 | G141: 60 | H141: =_xlfn.XLOOKUP($B141,'[1]FFPC TE'!$A$2:$A$46,'[1]FFPC TE'!B$2:B$46,,0) -> 13.7 | I141: =_xlfn.XLOOKUP($B141,'[1]FFPC TE'!$A$2:$A$46,'[1]FFPC TE'!C$2:C$46,,0) -> 12.1 | J141: =_xlfn.XLOOKUP($B141,'[1]FFPC TE'!$A$2:$A$46,'[1]FFPC TE'!D$2:D$46,,0) -> 8.6 | K141: =_xlfn.XLOOKUP($B141,'[1]FFPC TE'!$A$2:$A$46,'[1]FFPC TE'!E$2:E$46,,0) -> 12.3 | L141: =_xlfn.XLOOKUP($B141,'[1]FFPC TE'!$A$2:$A$46,'[1]FFPC TE'!F$2:F$46,,0) -> 22.6 | M141: =_xlfn.XLOOKUP($B141,'[1]FFPC TE'!$A$2:$A$46,'[1]FFPC TE'!G$2:G$46,,0) -> 16.8 | N141: =_xlfn.XLOOKUP($B141,'[1]FFPC TE'!$A$2:$A$46,'[1]FFPC TE'!H$2:H$46,,0) -> 9.9 | O141: =_xlfn.XLOOKUP($B141,'[1]FFPC TE'!$A$2:$A$46,'[1]FFPC TE'!I$2:I$46,,0) -> 24.9 | ... X141: =_xlfn.XLOOKUP($B141,'[1]FFPC TE'!$A$2:$A$46,'[1]FFPC TE'!R$2:R$46,,0) -> 11.1 | Y141: =SUM(H141:X141) -> 223.4 | Z141: 11.4 | AA141: 7 | AB141: 1 | AC141: 9 | AD141: 4 | AE141: 2 | AF141: 0 | AG141: 0 | AH141: 0.52941176 | AI141: 0.23529412 | AJ141: 0.11764706 | AK141: 0 | AL141: 0
A142: 2025 | B142: Tyler Warren | C142: IND | D142: {=_xlfn.XLOOKUP(1,('26 WR'!A:A=E142)*('26 WR'!B:B=F142),'26 WR'!C:C)} -> Tucker Kraft | E142: TE | F142: 6 | G142: 64 | H142: =_xlfn.XLOOKUP($B142,'[1]FFPC TE'!$A$2:$A$46,'[1]FFPC TE'!B$2:B$46,,0) -> 18.1 | I142: =_xlfn.XLOOKUP($B142,'[1]FFPC TE'!$A$2:$A$46,'[1]FFPC TE'!C$2:C$46,,0) -> 13.9 | J142: =_xlfn.XLOOKUP($B142,'[1]FFPC TE'!$A$2:$A$46,'[1]FFPC TE'!D$2:D$46,,0) -> 8.3 | K142: =_xlfn.XLOOKUP($B142,'[1]FFPC TE'!$A$2:$A$46,'[1]FFPC TE'!E$2:E$46,,0) -> 14.5 | L142: =_xlfn.XLOOKUP($B142,'[1]FFPC TE'!$A$2:$A$46,'[1]FFPC TE'!F$2:F$46,,0) -> 16.4 | M142: =_xlfn.XLOOKUP($B142,'[1]FFPC TE'!$A$2:$A$46,'[1]FFPC TE'!G$2:G$46,,0) -> 21.3 | N142: =_xlfn.XLOOKUP($B142,'[1]FFPC TE'!$A$2:$A$46,'[1]FFPC TE'!H$2:H$46,,0) -> 18.9 | O142: =_xlfn.XLOOKUP($B142,'[1]FFPC TE'!$A$2:$A$46,'[1]FFPC TE'!I$2:I$46,,0) -> 11.3 | ... X142: =_xlfn.XLOOKUP($B142,'[1]FFPC TE'!$A$2:$A$46,'[1]FFPC TE'!R$2:R$46,,0) -> 11.8 | Y142: =SUM(H142:X142) -> 209.6 | Z142: 11.1 | AA142: 7 | AB142: 1 | AC142: 8 | AD142: 4 | AE142: 0 | AF142: 0 | AG142: 0 | AH142: 0.47058824 | AI142: 0.23529412 | AJ142: 0 | AK142: 0 | AL142: 0
A143: 2025 | B143: T.J. Hockenson | C143: MIN | D143: {=_xlfn.XLOOKUP(1,('26 WR'!A:A=E143)*('26 WR'!B:B=F143),'26 WR'!C:C)} -> Kyle Pitts Sr. | E143: TE | F143: 7 | G143: 65 | H143: =_xlfn.XLOOKUP($B143,'[1]FFPC TE'!$A$2:$A$46,'[1]FFPC TE'!B$2:B$46,,0) -> 6 | I143: =_xlfn.XLOOKUP($B143,'[1]FFPC TE'!$A$2:$A$46,'[1]FFPC TE'!C$2:C$46,,0) -> 2.7 | J143: =_xlfn.XLOOKUP($B143,'[1]FFPC TE'!$A$2:$A$46,'[1]FFPC TE'!D$2:D$46,,0) -> 18.4 | K143: =_xlfn.XLOOKUP($B143,'[1]FFPC TE'!$A$2:$A$46,'[1]FFPC TE'!E$2:E$46,,0) -> 9.9 | L143: =_xlfn.XLOOKUP($B143,'[1]FFPC TE'!$A$2:$A$46,'[1]FFPC TE'!F$2:F$46,,0) -> 12.8 | M143: =_xlfn.XLOOKUP($B143,'[1]FFPC TE'!$A$2:$A$46,'[1]FFPC TE'!G$2:G$46,,0) -> 0 | N143: =_xlfn.XLOOKUP($B143,'[1]FFPC TE'!$A$2:$A$46,'[1]FFPC TE'!H$2:H$46,,0) -> 13.3 | O143: =_xlfn.XLOOKUP($B143,'[1]FFPC TE'!$A$2:$A$46,'[1]FFPC TE'!I$2:I$46,,0) -> 5.6 | ... X143: =_xlfn.XLOOKUP($B143,'[1]FFPC TE'!$A$2:$A$46,'[1]FFPC TE'!R$2:R$46,,0) -> 0 | Y143: =SUM(H143:X143) -> 138.3 | Z143: 7.5 | AA143: 7 | AB143: 1 | AC143: 4 | AD143: 1 | AE143: 0 | AF143: 0 | AG143: 0 | AH143: 0.23529412 | AI143: 0.066666667 | AJ143: 0 | AK143: 0 | AL143: 0
A144: 2025 | B144: Evan Engram | C144: DEN | D144: {=_xlfn.XLOOKUP(1,('26 WR'!A:A=E144)*('26 WR'!B:B=F144),'26 WR'!C:C)} -> Sam LaPorta | E144: TE | F144: 8 | G144: 89 | H144: =_xlfn.XLOOKUP($B144,'[1]FFPC TE'!$A$2:$A$46,'[1]FFPC TE'!B$2:B$46,,0) -> 6.6 | I144: =_xlfn.XLOOKUP($B144,'[1]FFPC TE'!$A$2:$A$46,'[1]FFPC TE'!C$2:C$46,,0) -> 2.7 | J144: =_xlfn.XLOOKUP($B144,'[1]FFPC TE'!$A$2:$A$46,'[1]FFPC TE'!D$2:D$46,,0) -> 0 | K144: =_xlfn.XLOOKUP($B144,'[1]FFPC TE'!$A$2:$A$46,'[1]FFPC TE'!E$2:E$46,,0) -> 8.9 | L144: =_xlfn.XLOOKUP($B144,'[1]FFPC TE'!$A$2:$A$46,'[1]FFPC TE'!F$2:F$46,,0) -> 15.3 | M144: =_xlfn.XLOOKUP($B144,'[1]FFPC TE'!$A$2:$A$46,'[1]FFPC TE'!G$2:G$46,,0) -> 11.7 | N144: =_xlfn.XLOOKUP($B144,'[1]FFPC TE'!$A$2:$A$46,'[1]FFPC TE'!H$2:H$46,,0) -> 11.7 | O144: =_xlfn.XLOOKUP($B144,'[1]FFPC TE'!$A$2:$A$46,'[1]FFPC TE'!I$2:I$46,,0) -> 9.6 | ... X144: =_xlfn.XLOOKUP($B144,'[1]FFPC TE'!$A$2:$A$46,'[1]FFPC TE'!R$2:R$46,,0) -> 8.1 | Y144: =SUM(H144:X144) -> 118.1 | Z144: 6.4 | AA144: 8 | AB144: 1 | AC144: 2 | AD144: 0 | AE144: 0 | AF144: 0 | AG144: 0 | AH144: 0.11764706 | AI144: 0 | AJ144: 0 | AK144: 0 | AL144: 0
A145: 2025 | B145: Mark Andrews | C145: BAL | D145: {=_xlfn.XLOOKUP(1,('26 WR'!A:A=E145)*('26 WR'!B:B=F145),'26 WR'!C:C)} -> Travis Kelce | E145: TE | F145: 9 | G145: 91 | H145: =_xlfn.XLOOKUP($B145,'[1]FFPC TE'!$A$2:$A$46,'[1]FFPC TE'!B$2:B$46,,0) -> 2 | I145: =_xlfn.XLOOKUP($B145,'[1]FFPC TE'!$A$2:$A$46,'[1]FFPC TE'!C$2:C$46,,0) -> 1.7 | J145: =_xlfn.XLOOKUP($B145,'[1]FFPC TE'!$A$2:$A$46,'[1]FFPC TE'!D$2:D$46,,0) -> 30.1 | K145: =_xlfn.XLOOKUP($B145,'[1]FFPC TE'!$A$2:$A$46,'[1]FFPC TE'!E$2:E$46,,0) -> 13.5 | L145: =_xlfn.XLOOKUP($B145,'[1]FFPC TE'!$A$2:$A$46,'[1]FFPC TE'!F$2:F$46,,0) -> 5.2 | M145: =_xlfn.XLOOKUP($B145,'[1]FFPC TE'!$A$2:$A$46,'[1]FFPC TE'!G$2:G$46,,0) -> 8.4 | N145: =_xlfn.XLOOKUP($B145,'[1]FFPC TE'!$A$2:$A$46,'[1]FFPC TE'!H$2:H$46,,0) -> 0 | O145: =_xlfn.XLOOKUP($B145,'[1]FFPC TE'!$A$2:$A$46,'[1]FFPC TE'!I$2:I$46,,0) -> 7.9 | ... X145: =_xlfn.XLOOKUP($B145,'[1]FFPC TE'!$A$2:$A$46,'[1]FFPC TE'!R$2:R$46,,0) -> 8.8 | Y145: =SUM(H145:X145) -> 139.8 | Z145: 7.7 | AA145: 9 | AB145: 1 | AC145: 4 | AD145: 3 | AE145: 1 | AF145: 1 | AG145: 0 | AH145: 0.23529412 | AI145: 0.17647059 | AJ145: 0.058823529 | AK145: 0.058823529 | AL145: 0
A146: 2025 | B146: David Njoku | C146: CLE | D146: {=_xlfn.XLOOKUP(1,('26 WR'!A:A=E146)*('26 WR'!B:B=F146),'26 WR'!C:C)} -> Jake Ferguson | E146: TE | F146: 10 | G146: 96 | H146: =_xlfn.XLOOKUP($B146,'[1]FFPC TE'!$A$2:$A$46,'[1]FFPC TE'!B$2:B$46,,0) -> 8.2 | I146: =_xlfn.XLOOKUP($B146,'[1]FFPC TE'!$A$2:$A$46,'[1]FFPC TE'!C$2:C$46,,0) -> 10 | J146: =_xlfn.XLOOKUP($B146,'[1]FFPC TE'!$A$2:$A$46,'[1]FFPC TE'!D$2:D$46,,0) -> 11.5 | K146: =_xlfn.XLOOKUP($B146,'[1]FFPC TE'!$A$2:$A$46,'[1]FFPC TE'!E$2:E$46,,0) -> 4.1 | L146: =_xlfn.XLOOKUP($B146,'[1]FFPC TE'!$A$2:$A$46,'[1]FFPC TE'!F$2:F$46,,0) -> 21.7 | M146: =_xlfn.XLOOKUP($B146,'[1]FFPC TE'!$A$2:$A$46,'[1]FFPC TE'!G$2:G$46,,0) -> 7.3 | N146: =_xlfn.XLOOKUP($B146,'[1]FFPC TE'!$A$2:$A$46,'[1]FFPC TE'!H$2:H$46,,0) -> 0 | O146: =_xlfn.XLOOKUP($B146,'[1]FFPC TE'!$A$2:$A$46,'[1]FFPC TE'!I$2:I$46,,0) -> 15.7 | ... X146: =_xlfn.XLOOKUP($B146,'[1]FFPC TE'!$A$2:$A$46,'[1]FFPC TE'!R$2:R$46,,0) -> 0 | Y146: =SUM(H146:X146) -> 102.8 | Z146: 7.2 | AA146: 9 | AB146: 1 | AC146: 3 | AD146: 1 | AE146: 0 | AF146: 0 | AG146: 0 | AH146: 0.17647059 | AI146: 0.083333333 | AJ146: 0 | AK146: 0 | AL146: 0
A147: 2025 | B147: Colston Loveland | C147: CHI | D147: {=_xlfn.XLOOKUP(1,('26 WR'!A:A=E147)*('26 WR'!B:B=F147),'26 WR'!C:C)} -> Dalton Kincaid | E147: TE | F147: 11 | G147: 99 | H147: =_xlfn.XLOOKUP($B147,'[1]FFPC TE'!$A$2:$A$46,'[1]FFPC TE'!B$2:B$46,,0) -> 4.2 | I147: =_xlfn.XLOOKUP($B147,'[1]FFPC TE'!$A$2:$A$46,'[1]FFPC TE'!C$2:C$46,,0) -> 0 | J147: =_xlfn.XLOOKUP($B147,'[1]FFPC TE'!$A$2:$A$46,'[1]FFPC TE'!D$2:D$46,,0) -> 4.6 | K147: =_xlfn.XLOOKUP($B147,'[1]FFPC TE'!$A$2:$A$46,'[1]FFPC TE'!E$2:E$46,,0) -> 0 | L147: =_xlfn.XLOOKUP($B147,'[1]FFPC TE'!$A$2:$A$46,'[1]FFPC TE'!F$2:F$46,,0) -> 0 | M147: =_xlfn.XLOOKUP($B147,'[1]FFPC TE'!$A$2:$A$46,'[1]FFPC TE'!G$2:G$46,,0) -> 4.1 | N147: =_xlfn.XLOOKUP($B147,'[1]FFPC TE'!$A$2:$A$46,'[1]FFPC TE'!H$2:H$46,,0) -> 6.9 | O147: =_xlfn.XLOOKUP($B147,'[1]FFPC TE'!$A$2:$A$46,'[1]FFPC TE'!I$2:I$46,,0) -> 8.3 | ... X147: =_xlfn.XLOOKUP($B147,'[1]FFPC TE'!$A$2:$A$46,'[1]FFPC TE'!R$2:R$46,,0) -> 24.4 | Y147: =SUM(H147:X147) -> 164.2 | Z147: 10.3 | AA147: 9 | AB147: 1 | AC147: 6 | AD147: 3 | AE147: 3 | AF147: 2 | AG147: 0 | AH147: 0.35294118 | AI147: 0.1875 | AJ147: 0.1875 | AK147: 0.125 | AL147: 0
A148: 2025 | B148: Tucker Kraft | C148: GB | D148: {=_xlfn.XLOOKUP(1,('26 WR'!A:A=E148)*('26 WR'!B:B=F148),'26 WR'!C:C)} -> George Kittle | E148: TE | F148: 12 | G148: 102 | H148: =_xlfn.XLOOKUP($B148,'[1]FFPC TE'!$A$2:$A$46,'[1]FFPC TE'!B$2:B$46,,0) -> 10.6 | I148: =_xlfn.XLOOKUP($B148,'[1]FFPC TE'!$A$2:$A$46,'[1]FFPC TE'!C$2:C$46,,0) -> 27.4 | J148: =_xlfn.XLOOKUP($B148,'[1]FFPC TE'!$A$2:$A$46,'[1]FFPC TE'!D$2:D$46,,0) -> 7.4 | K148: =_xlfn.XLOOKUP($B148,'[1]FFPC TE'!$A$2:$A$46,'[1]FFPC TE'!E$2:E$46,,0) -> 13.1 | L148: =_xlfn.XLOOKUP($B148,'[1]FFPC TE'!$A$2:$A$46,'[1]FFPC TE'!F$2:F$46,,0) -> 0 | M148: =_xlfn.XLOOKUP($B148,'[1]FFPC TE'!$A$2:$A$46,'[1]FFPC TE'!G$2:G$46,,0) -> 13.3 | N148: =_xlfn.XLOOKUP($B148,'[1]FFPC TE'!$A$2:$A$46,'[1]FFPC TE'!H$2:H$46,,0) -> 19.3 | O148: =_xlfn.XLOOKUP($B148,'[1]FFPC TE'!$A$2:$A$46,'[1]FFPC TE'!I$2:I$46,,0) -> 36.8 | ... X148: =_xlfn.XLOOKUP($B148,'[1]FFPC TE'!$A$2:$A$46,'[1]FFPC TE'!R$2:R$46,,0) -> 0 | Y148: =SUM(H148:X148) -> 132.9 | Z148: 14.7 | AA148: 10 | AB148: 1 | AC148: 5 | AD148: 3 | AE148: 2 | AF148: 1 | AG148: 1 | AH148: 0.29411765 | AI148: 0.375 | AJ148: 0.25 | AK148: 0.125 | AL148: 0.125
... A181: 2025 | B181: AJ Barner | C181: SEA | D181: {=_xlfn.XLOOKUP(1,('26 WR'!A:A=E181)*('26 WR'!B:B=F181),'26 WR'!C:C)} -> Ja'Tavion Sanders | E181: TE | F181: 45 | G181: 296 | H181: =_xlfn.XLOOKUP($B181,'[1]FFPC TE'!$A$2:$A$46,'[1]FFPC TE'!B$2:B$46,,0) -> 1.5 | I181: =_xlfn.XLOOKUP($B181,'[1]FFPC TE'!$A$2:$A$46,'[1]FFPC TE'!C$2:C$46,,0) -> 11.6 | J181: =_xlfn.XLOOKUP($B181,'[1]FFPC TE'!$A$2:$A$46,'[1]FFPC TE'!D$2:D$46,,0) -> 3.8 | K181: =_xlfn.XLOOKUP($B181,'[1]FFPC TE'!$A$2:$A$46,'[1]FFPC TE'!E$2:E$46,,0) -> 13.7 | L181: =_xlfn.XLOOKUP($B181,'[1]FFPC TE'!$A$2:$A$46,'[1]FFPC TE'!F$2:F$46,,0) -> 27.8 | M181: =_xlfn.XLOOKUP($B181,'[1]FFPC TE'!$A$2:$A$46,'[1]FFPC TE'!G$2:G$46,,0) -> 11.6 | N181: =_xlfn.XLOOKUP($B181,'[1]FFPC TE'!$A$2:$A$46,'[1]FFPC TE'!H$2:H$46,,0) -> 0 | O181: =_xlfn.XLOOKUP($B181,'[1]FFPC TE'!$A$2:$A$46,'[1]FFPC TE'!I$2:I$46,,0) -> 0 | ... X181: =_xlfn.XLOOKUP($B181,'[1]FFPC TE'!$A$2:$A$46,'[1]FFPC TE'!R$2:R$46,,0) -> 14.8 | Y181: =SUM(H181:X181) -> 159.3 | Z181: 8.7 | AA181: 20 | AB181: 1 | AC181: 8 | AD181: 2 | AE181: 1 | AF181: 0 | AG181: 0 | AH181: 0.47058824 | AI181: 0.11764706 | AJ181: 0.058823529 | AK181: 0 | AL181: 0
A182: 2025 | B182: Ja'Marr Chase | C182: CIN | D182: {=_xlfn.XLOOKUP(1,('26 WR'!A:A=E182)*('26 WR'!B:B=F182),'26 WR'!C:C)} -> Ja'Marr Chase | E182: WR | F182: 1 | G182: 1 | H182: 4.6 | I182: 36.5 | J182: 8.9 | K182: 7.3 | L182: 29 | M182: 25.1 | N182: 38.1 | O182: 21.1 | P182: 17.1 | Q182: 0 | R182: 6 | S182: 0 | T182: 18 | U182: 10.2 | V182: 23.2 | W182: 19.9 | X182: 25 | Y182: =SUM(H182:X182) -> 290 | Z182: 19.6 | AA182: 1 | AB182: 1 | AC182: 12 | AD182: 11 | AE182: 8 | AF182: 4 | AG182: 2 | AH182: 0.70588235 | AI182: 0.6875 | AJ182: 0.5 | AK182: 0.25 | AL182: 0.125
A183: 2025 | B183: Justin Jefferson | C183: MIN | D183: {=_xlfn.XLOOKUP(1,('26 WR'!A:A=E183)*('26 WR'!B:B=F183),'26 WR'!C:C)} -> Puka Nacua | E183: WR | F183: 2 | G183: 7 | H183: 14.8 | I183: 11.1 | J183: 12.5 | K183: 22.6 | L183: 19.3 | M183: 0 | N183: 12.9 | O183: 14.4 | P183: 16.7 | Q183: 7.7 | R183: 11.1 | S183: 8.8 | T183: 2.4 | U183: 3.1 | V183: 4.2 | W183: 14.5 | X183: 7 | Y183: =SUM(H183:X183) -> 183.1 | Z183: 11.9 | AA183: 1 | AB183: 1 | AC183: 11 | AD183: 4 | AE183: 1 | AF183: 0 | AG183: 0 | AH183: 0.64705882 | AI183: 0.23529412 | AJ183: 0.058823529 | AK183: 0 | AL183: 0
A184: 2025 | B184: CeeDee Lamb | C184: DAL | D184: {=_xlfn.XLOOKUP(1,('26 WR'!A:A=E184)*('26 WR'!B:B=F184),'26 WR'!C:C)} -> Jaxon Smith-Njigba | E184: WR | F184: 3 | G184: 9 | H184: 18 | I184: 20.2 | J184: 0 | K184: 0 | L184: 0 | M184: 0 | N184: 22 | O184: 14.6 | P184: 15.5 | Q184: 0 | R184: 17.6 | S184: 11.5 | T184: 24.2 | U184: 18.1 | V184: 17.1 | W184: 11.1 | X184: 9.6 | Y184: =SUM(H184:X184) -> 199.5 | Z184: 14.4 | AA184: 1 | AB184: 1 | AC184: 11 | AD184: 8 | AE184: 3 | AF184: 0 | AG184: 0 | AH184: 0.64705882 | AI184: 0.57142857 | AJ184: 0.21428571 | AK184: 0 | AL184: 0
A185: 2025 | B185: Nico Collins | C185: HOU | D185: {=_xlfn.XLOOKUP(1,('26 WR'!A:A=E185)*('26 WR'!B:B=F185),'26 WR'!C:C)} -> Amon-Ra St. Brown | E185: WR | F185: 4 | G185: 12 | H185: 5.5 | I185: 14.2 | J185: 22.4 | K185: 11.9 | L185: 16 | M185: 0 | N185: 6.7 | O185: 0 | P185: 14.5 | Q185: 22.6 | R185: 24.2 | S185: 8.5 | T185: 21.5 | U185: 16.1 | V185: 23.5 | W185: 9.9 | X185: 8.7 | Y185: =SUM(H185:X185) -> 226.2 | Z185: 15.1 | AA185: 1 | AB185: 1 | AC185: 10 | AD185: 7 | AE185: 5 | AF185: 0 | AG185: 0 | AH185: 0.58823529 | AI185: 0.46666667 | AJ185: 0.33333333 | AK185: 0 | AL185: 0
A186: 2025 | B186: Malik Nabers | C186: NYG | D186: {=_xlfn.XLOOKUP(1,('26 WR'!A:A=E186)*('26 WR'!B:B=F186),'26 WR'!C:C)} -> CeeDee Lamb | E186: WR | F186: 5 | G186: 15 | H186: 12.1 | I186: 37.7 | J186: 3.3 | K186: 4 | L186: 0 | M186: 0 | N186: 0 | O186: 0 | P186: 0 | Q186: 0 | R186: 0 | S186: 0 | T186: 0 | U186: 0 | V186: 0 | W186: 0 | X186: 0 | Y186: =SUM(H186:X186) -> 57.1 | Z186: 14.3 | AA186: 1 | AB186: 1 | AC186: 2 | AD186: 1 | AE186: 1 | AF186: 1 | AG186: 1 | AH186: 0.11764706 | AI186: 0.25 | AJ186: 0.25 | AK186: 0.25 | AL186: 0.25
A187: 2025 | B187: Amon-Ra St. Brown | C187: DET | D187: {=_xlfn.XLOOKUP(1,('26 WR'!A:A=E187)*('26 WR'!B:B=F187),'26 WR'!C:C)} -> Justin Jefferson | E187: WR | F187: 6 | G187: 18 | H187: 8.5 | I187: 39.2 | J187: 20.7 | K187: 26 | L187: 18 | M187: 13.7 | N187: 20.6 | O187: 0 | P187: 18.7 | Q187: 16.8 | R187: 6.2 | S187: 29.9 | T187: 0 | U187: 15.2 | V187: 41.4 | W187: 9.4 | X187: 14.8 | Y187: =SUM(H187:X187) -> 299.1 | Z187: 19.1 | AA187: 1 | AB187: 1 | AC187: 13 | AD187: 11 | AE187: 7 | AF187: 4 | AG187: 2 | AH187: 0.76470588 | AI187: 0.64705882 | AJ187: 0.41176471 | AK187: 0.23529412 | AL187: 0.11764706
A188: 2025 | B188: Puka Nacua | C188: LAR | D188: {=_xlfn.XLOOKUP(1,('26 WR'!A:A=E188)*('26 WR'!B:B=F188),'26 WR'!C:C)} -> Drake London | E188: WR | F188: 7 | G188: 21 | H188: 23.1 | I188: 27.6 | J188: 22.8 | K188: 36 | L188: 24.5 | M188: 4.8 | N188: 0 | O188: 0 | P188: 22.8 | Q188: 17.4 | R188: 14.3 | S188: 16.7 | T188: 13.2 | U188: 35.7 | V188: 27.9 | W188: 46.5 | X188: 15.7 | Y188: =SUM(H188:X188) -> 349 | Z188: 23.4 | AA188: 2 | AB188: 1 | AC188: 15 | AD188: 13 | AE188: 10 | AF188: 6 | AG188: 3 | AH188: 0.88235294 | AI188: 0.8125 | AJ188: 0.625 | AK188: 0.375 | AL188: 0.1875
A189: 2025 | B189: Brian Thomas Jr. | C189: JAC | D189: {=_xlfn.XLOOKUP(1,('26 WR'!A:A=E189)*('26 WR'!B:B=F189),'26 WR'!C:C)} -> Nico Collins | E189: WR | F189: 8 | G189: 22 | H189: 9 | I189: 8.9 | J189: 7.5 | K189: 10.6 | L189: 12 | M189: 23 | N189: 6.1 | O189: 0 | P189: 8.5 | Q189: 0 | R189: 0 | S189: 0 | T189: 4.8 | U189: 11.7 | V189: 17.1 | W189: 3.8 | X189: 7.9 | Y189: =SUM(H189:X189) -> 130.9 | Z189: 9.9 | AA189: 2 | AB189: 1 | AC189: 5 | AD189: 2 | AE189: 1 | AF189: 0 | AG189: 0 | AH189: 0.29411765 | AI189: 0.14285714 | AJ189: 0.071428571 | AK189: 0 | AL189: 0
A190: 2025 | B190: Drake London | C190: ATL | D190: {=_xlfn.XLOOKUP(1,('26 WR'!A:A=E190)*('26 WR'!B:B=F190),'26 WR'!C:C)} -> A.J. Brown | E190: WR | F190: 9 | G190: 24 | H190: 13.5 | I190: 5.9 | J190: 10.5 | K190: 25 | L190: 0 | M190: 31.8 | N190: 8.2 | O190: 0 | P190: 38.8 | Q190: 24.4 | R190: 18.9 | S190: 0 | T190: 0 | U190: 0 | V190: 0 | W190: 5.7 | X190: 1.4 | Y190: =SUM(H190:X190) -> 184.1 | Z190: 16.8 | AA190: 2 | AB190: 1 | AC190: 8 | AD190: 6 | AE190: 4 | AF190: 2 | AG190: 2 | AH190: 0.47058824 | AI190: 0.5 | AJ190: 0.33333333 | AK190: 0.16666667 | AL190: 0.16666667
A191: 2025 | B191: A.J. Brown | C191: PHI | D191: {=_xlfn.XLOOKUP(1,('26 WR'!A:A=E191)*('26 WR'!B:B=F191),'26 WR'!C:C)} -> George Pickens | E191: WR | F191: 10 | G191: 30 | H191: 1.8 | I191: 7.7 | J191: 22.9 | K191: 2.7 | L191: 9.3 | M191: 14 | N191: 28.1 | O191: 0 | P191: 0 | Q191: 3.3 | R191: 11.9 | S191: 25 | T191: 35.2 | U191: 16 | V191: 12.1 | W191: 18.5 | X191: 11.8 | Y191: =SUM(H191:X191) -> 220.3 | Z191: 14.7 | AA191: 2 | AB191: 1 | AC191: 10 | AD191: 6 | AE191: 4 | AF191: 2 | AG191: 1 | AH191: 0.58823529 | AI191: 0.4 | AJ191: 0.26666667 | AK191: 0.13333333 | AL191: 0.066666667
A192: 2025 | B192: Ladd McConkey | C192: LAC | D192: {=_xlfn.XLOOKUP(1,('26 WR'!A:A=E192)*('26 WR'!B:B=F192),'26 WR'!C:C)} -> Chris Olave | E192: WR | F192: 11 | G192: 33 | H192: 13.4 | I192: 9.8 | J192: 8.1 | K192: 2.1 | L192: 14.9 | M192: 23 | N192: 15.7 | O192: 20.8 | P192: 9.6 | Q192: 20.7 | R192: 4.3 | S192: 0 | T192: 13.9 | U192: 2.2 | V192: 4 | W192: 14.3 | X192: 4.1 | Y192: =SUM(H192:X192) -> 180.9 | Z192: 11.3 | AA192: 2 | AB192: 1 | AC192: 8 | AD192: 4 | AE192: 3 | AF192: 0 | AG192: 0 | AH192: 0.47058824 | AI192: 0.25 | AJ192: 0.1875 | AK192: 0 | AL192: 0
A193: 2025 | B193: Tee Higgins | C193: CIN | D193: {=_xlfn.XLOOKUP(1,('26 WR'!A:A=E193)*('26 WR'!B:B=F193),'26 WR'!C:C)} -> Rashee Rice | E193: WR | F193: 12 | G193: 35 | H193: 6.3 | I193: 14.6 | J193: 2.5 | K193: 6.2 | L193: 11.2 | M193: 11.2 | N193: 21.6 | O193: 11.4 | P193: 33.1 | Q193: 0 | R193: 15.3 | S193: 8.1 | T193: 0 | U193: 27.2 | V193: 0 | W193: 14.3 | X193: 9.9 | Y193: =SUM(H193:X193) -> 192.9 | Z193: 14.1 | AA193: 3 | AB193: 1 | AC193: 10 | AD193: 5 | AE193: 3 | AF193: 2 | AG193: 1 | AH193: 0.58823529 | AI193: 0.33333333 | AJ193: 0.2 | AK193: 0.13333333 | AL193: 0.066666667
... A300: 2025 | B300: Isaiah Williams | C300: NYJ | D300: {=_xlfn.XLOOKUP(1,('26 WR'!A:A=E300)*('26 WR'!B:B=F300),'26 WR'!C:C)} -> Jahan Dotson | E300: WR | F300: 119 | G300: 299 | H300: 0 | I300: 0 | J300: 0 | K300: 2 | L300: 0 | M300: 0 | N300: 0 | O300: 8.6 | P300: 0 | Q300: 7.4 | R300: 1.6 | S300: 0 | T300: 0 | U300: 10.4 | V300: 11.3 | W300: 6.5 | X300: 7.5 | Y300: =SUM(H300:X300) -> 55.3 | Z300: 3.9 | AA300: 20 | AB300: 1 | AC300: 2 | AD300: 0 | AE300: 0 | AF300: 0 | AG300: 0 | AH300: 0.11764706 | AI300: 0 | AJ300: 0 | AK300: 0 | AL300: 0
...

Sheet Sheet2
A1: Ja'Marr Chase | B1: WR | C1: 1
A2: Justin Jefferson | B2: WR | C2: 2
A3: CeeDee Lamb | B3: WR | C3: 3
A4: Nico Collins | B4: WR | C4: 4
A5: Malik Nabers | B5: WR | C5: 5
A6: Amon-Ra St. Brown | B6: WR | C6: 6
A7: Puka Nacua | B7: WR | C7: 7
A8: Brian Thomas Jr. | B8: WR | C8: 8
A9: Drake London | B9: WR | C9: 9
A10: A.J. Brown | B10: WR | C10: 10
A11: Ladd McConkey | B11: WR | C11: 11
A12: Tee Higgins | B12: WR | C12: 12
... A119: Isaiah Williams | B119: WR | C119: 119

Sheet 26 WR
A1: Position | B1: RK | C1: PLAYER NAME | D1: TEAM
A2: WR | B2: 1 | C2: Ja'Marr Chase | D2: CIN
A3: WR | B3: 2 | C3: Puka Nacua | D3: LAR
A4: WR | B4: 3 | C4: Jaxon Smith-Njigba | D4: SEA
A5: WR | B5: 4 | C5: Amon-Ra St. Brown | D5: DET
A6: WR | B6: 5 | C6: CeeDee Lamb | D6: DAL
A7: WR | B7: 6 | C7: Justin Jefferson | D7: MIN
A8: WR | B8: 7 | C8: Drake London | D8: ATL
A9: WR | B9: 8 | C9: Nico Collins | D9: HOU
A10: WR | B10: 9 | C10: A.J. Brown | D10: NE
A11: WR | B11: 10 | C11: George Pickens | D11: DAL
A12: WR | B12: 11 | C12: Chris Olave | D12: NO
A13: WR | B13: 12 | C13: Rashee Rice | D13: KC
... A349: QB | B349: 42 | C349: Joe Flacco | D349: CIN
